Workbook

Sheet Details projection
A1: PROJECTION CASHFLOWS/2025 (REVENUES AND EXPENSES)
A3: S/N | B3: DESCRIPTION | C3: DETAILS | D3: AMOUNT
A4: 1 | B4: BALANCE AT THE BANK AS ON 11/03/2025 | C4: BANKS | D4: 646571756
C5: MOMO | D5: 5678597
A6: 2 | B6: RECEIVABLES | C6: BRITAM INSURANCE | D6: 179695570
C7: VAT | D7: =120000000*10 -> 1200000000
C8: MSF | D8: =11000000*10 -> 110000000
C9: MEMBERSHIP CONTRIBUTION PENDING | D9: 2200000
C10: MEMBERSHIP CONTRIBUTION | D10: 20000000
C11: COMMITMENT SHARES | D11: 30000000
C12: REPAYMENT LOON (STAFF) | D12: 10000000
C13: DIVIDEND FROM INVESTMENT IN SHARES (ACB) | D13: 0
C14: RTB/RPL | D14: 28680000
B15: TOTAL RECEIBLES AND BANK BALANCES | C15: BANK,MOMO,RTB,INSURANCE | D15: =SUM(D4:D14) -> 2232825923
D16: Expenses per month | E16: Expense per year
A17: 1 | B17: TOTAL PAYABLES | C17: DESKS /Amendment.Guarantee(performance security) | D17: =+E17 -> 408458207 | E17: 408458207
C18: VAT | D18: 119000000 | E18: =+D18*11 -> 1309000000
B19: OVERHEAD EXPENSES | C19: GROSS SALARIES | D19: =20368714 -> 20368714 | E19: =+D19*10 -> 203687140
C20: LUMP SUM | D20: 1000000 | E20: =+D20*10 -> 10000000
C21: FUEL | D21: 1600000 | E21: =+D21*10 -> 16000000
C22: INTERNET&AIRTIME | D22: 650000 | E22: =+D22*9 -> 5850000
C23: ELECTRICITY | D23: 50000 | E23: =+D23*9 -> 450000
C24: WATER | D24: 50000 | E24: =+D24*12 -> 600000
C25: LEGAL SERVICE | D25: =590000 -> 590000 | E25: =+D25*11 -> 6490000
C26: INTERNAL AUDIT CONTROLER | D26: 1500000 | E26: =+D26*11 -> 16500000
C27: BANK CHARGES | D27: 800875 | E27: =+D27*10 -> 8008750
C28: SITTING ALLOWANCES | D28: 0 | E28: 4900000
C29: GENERAL ASSEMBLY | D29: 3500000 | E29: =+D29*2 -> 7000000
C30: MISSION FEES | D30: 250000 | E30: =+D30*10 -> 2500000
C31: RENT(FILD OFFICES) | D31: 0 | E31: 3462000
C32: RENT(HQ OFFICE ) | D32: 2000000 | E32: =+D32*3 -> 6000000
C33: OFFICE STATIONARIES | D33: 100000 | E33: =+D33*10 -> 1000000
C34: STAFFFOOD | D34: 1000000 | E34: =+D34*10 -> 10000000
C35: CAR WASH | D35: 250000 | E35: =+D35*10 -> 2500000
C36: REPAIR AND MAINTENANCE CARS | D36: 500000 | E36: =+D36*10 -> 5000000
C37: REPRESENTATION FEES | D37: 200000 | E37: =+D37*10 -> 2000000
C38: WHT 15% &30% | D38: 800000 | E38: =+D38*11 -> 8800000
C39: WAGE | D39: 250000 | E39: =+D39*10 -> 2500000
C40: OTHER EXPENSES | D40: 1000000 | E40: =+D40*10 -> 10000000
B41: TOTAL OVERHEAD EXPENSES | E41: =SUM(E19:E40) -> 333247890
...

Sheet Summary projection
A1: PROJECTION CASH FLOWS/2025 (REVENUES AND EXPENSES)
A3: S/N | B3: DESCRIPTION | C3: DETAILS | D3: AMOUNT
A4: 1 | B4: BALANCE AT THE BANK AS ON 11/03/2025 | C4: BANKS,MOMO | D4: =+'Details projection'!D4:E4+'Details projection'!D5:E5 -> 652250353
A5: 2 | B5: RECEIVABLES | C5: RTB,BRITAM INSURANCE,VAT,MSF,MEMBERSHIP CONTRIBUTIONS,REPAYMENT LOON AND COMMITMENT,DIVIDEND | D5: =+'Details projection'!D6:E6+'Details projection'!D7:E7+'Details projection'!D8:E8+'Details projection'!D9:E9+'Details projection'!D10:E10+'Details projection'!D11:E11+'Details projection'!D14:E14+'Summary projection'!E5+'Details projection'!D12:E12 -> 1580575570
B6: TOTAL PROJECTED | C6: BANKS &MOMO AND RECEIVABLES | D6: =+D4+D5 -> 2232825923
D7: EXPENSES PER YEAR
A8: 1 | B8: TOTAL PROJECTED PAYABLES | C8: DESKS /AMENDMENT,VAT,GUARANTEE | D8: =+'Details projection'!E17+'Details projection'!E18 -> 1717458207
A9: 2 | B9: TOTAL PROJECTED OVERHEAD EXPENSES | C9: FIXED EXPENSES AND OTHERS | D9: =+'Details projection'!E42 -> 2050706097
B10: TOTAL PROJECTED | C10: PAYABLES AND OVERHEADS | D10: =+'Details projection'!E42 -> 2050706097
B11: PROJECTED BALANCE AS ON 31.12.2026 | D11: =+D6-D10 -> 182119826
