Workbook

Sheet FINACHIAL REPORT
A1: RWVCA REPORT DATE ….........
A2: RWANDA WOOD VALUE CHAIN ASSOCIATION
A4: ICPCs NAME | B4: TVA IN | C4: MSF IN | D4: MS REGIS | E4: MS CONTR | F4: TVA+MSF | G4: FR NOT INVOICED | H4: MOMO | I4: PAID ON BANK | J4: CASH
A5: GISOZI | B5: =GISOZI!F57 -> 1.3337817e+08 | C5: =GISOZI!G57 -> 11062265 | D5: =GISOZI!C63 -> 0 | E5: =GISOZI!C64 -> 0 | F5: =SUM(B5:C5) -> 1.4444043e+08 | G5: =GISOZI!C61 -> 0 | H5: =GISOZI!C59 -> 144418433 | I5: =GISOZI!C62 -> 0 | J5: =GISOZI!C60 -> 0
A6: GAHANGA | B6: =GAHANGA!F37 -> 32429106 | C6: =GAHANGA!G37 -> 2790530 | D6: =GAHANGA!C43 -> 0 | E6: =GAHANGA!C44 -> 0 | F6: =SUM(B6:C6) -> 35219636 | G6: =GAHANGA!C41 -> 0 | H6: =GAHANGA!C39 -> 35219636 | I6: =GAHANGA!C42 -> 0 | J6: =GAHANGA!C40 -> 0
A7: KIMIROMKO | B7: =KIMIRONKO!F37 -> 43961918 | C7: =KIMIRONKO!G37 -> 3989250 | D7: =KIMIRONKO!C43 -> 0 | E7: =KIMIRONKO!C44 -> 0 | F7: =SUM(B7:C7) -> 47951168 | G7: =KIMIRONKO!C41 -> 0 | H7: =KIMIRONKO!C39 -> 0 | I7: =KIMIRONKO!C42 -> 0 | J7: =KIMIRONKO!C40 -> 0
A8: BISHENYI | B8: =BISHENYI!F37 -> 36607739 | C8: =BISHENYI!G37 -> 3043280 | D8: =BISHENYI!C43 -> 0 | E8: =BISHENYI!C44 -> 0 | F8: =SUM(B8:C8) -> 39651019 | G8: =BISHENYI!C41 -> 0 | H8: =BISHENYI!C39 -> 39653064 | I8: =BISHENYI!C42 -> 0 | J8: =BISHENYI!C40 -> 0
A9: RWAMAGANA | B9: =RWAMAGANA!F37 -> 13006128 | C9: =RWAMAGANA!G37 -> 1486781 | D9: =RWAMAGANA!C43 -> 0 | E9: =RWAMAGANA!C44 -> 800000 | F9: =SUM(B9:C9) -> 14492909 | G9: =RWAMAGANA!C41 -> 0 | H9: =RWAMAGANA!C39 -> 14492909 | I9: =RWAMAGANA!C42 -> 0 | J9: =RWAMAGANA!C40 -> 0
A10: BUGESERA | B10: =BUGESERA!F37 -> 44061174 | C10: =BUGESERA!G37 -> 4067790 | D10: =BUGESERA!C43 -> 0 | E10: =BUGESERA!C44 -> 0 | F10: =SUM(B10:C10) -> 48128964 | G10: =BUGESERA!C41 -> 0 | H10: =BUGESERA!C39 -> 45442312 | I10: =BUGESERA!C42 -> 0 | J10: =BUGESERA!C40 -> 2686652
A11: MUHANGA | B11: =MUHANGA!F37 -> 16087243 | C11: =MUHANGA!G37 -> 1381030 | D11: =MUHANGA!C43 -> 0 | E11: =MUHANGA!C44 -> 0 | F11: =SUM(B11:C11) -> 17468273 | G11: =MUHANGA!C41 -> 0 | H11: =MUHANGA!C39 -> 0 | I11: =MUHANGA!C42 -> 0 | J11: =MUHANGA!C40 -> 0
A12: RUHANGO | B12: =RUHANGO!F37 -> 1849728.8 | C12: =RUHANGO!G37 -> 594800 | D12: =RUHANGO!C43 -> 0 | E12: =RUHANGO!C44 -> 0 | F12: =SUM(B12:C12) -> 2444528.8 | G12: =RUHANGO!C41 -> 0 | H12: =RUHANGO!C39 -> 2444529 | I12: =RUHANGO!C42 -> 0 | J12: =RUHANGO!C40 -> 0
A13: HUYE | B13: =HUYE!F37 -> 14103728 | C13: =HUYE!G37 -> 1453620 | D13: =HUYE!C43 -> 0 | E13: =HUYE!C44 -> 0 | F13: =SUM(B13:C13) -> 15557348 | G13: =HUYE!C41 -> 0 | H13: =HUYE!C39 -> 0 | I13: =HUYE!C42 -> 0 | J13: =HUYE!C40 -> 0
A14: RUSIZI | B14: =RUSIZI!F37 -> 4761958.9 | C14: =RUSIZI!G37 -> 1040410 | D14: =RUSIZI!C43 -> 0 | E14: =RUSIZI!C44 -> 0 | F14: =SUM(B14:C14) -> 5802368.9 | G14: =RUSIZI!C41 -> 0 | H14: =RUSIZI!C39 -> 5802369 | I14: =RUSIZI!C42 -> 0 | J14: =RUSIZI!C40 -> 0
A15: NYAMAGABE | B15: =NYAMAGABE!F37 -> 0 | C15: =NYAMAGABE!G37 -> 0 | D15: =NYAMAGABE!C43 -> 0 | E15: =NYAMAGABE!C44 -> 0 | F15: =SUM(B15:C15) -> 0 | G15: =NYAMAGABE!C41 -> 0 | H15: =NYAMAGABE!C39 -> 316500 | I15: =NYAMAGABE!C42 -> 0 | J15: =NYAMAGABE!C40 -> 0
A16: KARONGI | B16: =KARONGI!F37 -> 5212535.8 | C16: =KARONGI!G37 -> 884978 | D16: =KARONGI!C43 -> 0 | E16: =KARONGI!C44 -> 0 | F16: =SUM(B16:C16) -> 6097513.8 | G16: =KARONGI!C41 -> 0 | H16: =KARONGI!C39 -> 6097514 | I16: =KARONGI!C42 -> 645430 | J16: =KARONGI!C40 -> 0
A17: RUBAVU | B17: =RUBAVU!F37 -> 13910148 | C17: =RUBAVU!G37 -> 1437418 | D17: =RUBAVU!C43 -> 0 | E17: =RUBAVU!C44 -> 0 | F17: =SUM(B17:C17) -> 15347566 | G17: =RUBAVU!C41 -> 0 | H17: =RUBAVU!C39 -> 14347566 | I17: =RUBAVU!C42 -> 1000000 | J17: =RUBAVU!C40 -> 0
A18: MUSANZE | B18: =MUSANZE!F37 -> 10958316 | C18: =MUSANZE!G37 -> 1300046 | D18: =MUSANZE!C43 -> 0 | E18: =MUSANZE!C44 -> 0 | F18: =SUM(B18:C18) -> 12258362 | G18: =MUSANZE!C41 -> 0 | H18: =MUSANZE!C39 -> 8700743 | I18: =MUSANZE!C42 -> 0 | J18: =MUSANZE!C40 -> 3557619
A19: KAYONZA | B19: =KAYONZA!F37 -> 7891110 | C19: =KAYONZA!G37 -> 721970 | D19: =KAYONZA!C43 -> 0 | E19: =KAYONZA!C44 -> 0 | F19: =SUM(B19:C19) -> 8613080 | G19: =KAYONZA!C41 -> 0 | H19: =KAYONZA!C39 -> 8926280 | I19: =KAYONZA!C42 -> 0 | J19: =KAYONZA!C40 -> 0
A20: NYAGATARE | B20: =NYAGATARE!F37 -> 5024402.2 | C20: =NYAGATARE!G37 -> 1076750 | D20: =NYAGATARE!C43 -> 0 | E20: =NYAGATARE!C44 -> 0 | F20: =SUM(B20:C20) -> 6101152.2 | G20: =NYAGATARE!C41 -> 0 | H20: =NYAGATARE!C39 -> 0 | I20: =NYAGATARE!C42 -> 0 | J20: =NYAGATARE!C40 -> 0
A21: KIREHE | B21: =KIREHE!F37 -> 5213268.8 | C21: =KIREHE!G37 -> 1208916 | D21: =KIREHE!C43 -> 0 | E21: =KIREHE!C44 -> 0 | F21: =SUM(B21:C21) -> 6422184.8 | G21: =KIREHE!C41 -> 0 | H21: =KIREHE!C39 -> 6422184.8 | I21: =KIREHE!C42 -> 0 | J21: =KIREHE!C40 -> 0
A22: NYANZA | B22: =NYANZA!F37 -> 1970847.5 | C22: =NYANZA!G37 -> 616200 | D22: =NYANZA!C43 -> 0 | E22: =NYANZA!C44 -> 0 | F22: =SUM(B22:C22) -> 2587047.5 | G22: =NYANZA!C41 -> 0 | H22: =NYANZA!C39 -> 2587047 | I22: =NYANZA!C42 -> 0 | J22: =NYANZA!C40 -> 0
A23: NYARUGENGE | B23: =NYARUGENGE!F37 -> 16261470 | C23: =NYARUGENGE!G37 -> 1488400 | D23: =NYARUGENGE!C43 -> 0 | E23: =NYARUGENGE!C44 -> 0 | F23: =SUM(B23:C23) -> 17749870 | G23: =NYARUGENGE!C41 -> 0 | H23: =NYARUGENGE!C39 -> 17749870 | I23: =NYARUGENGE!C42 -> 0 | J23: =NYARUGENGE!C40 -> 0
A24: GATSIBO | B24: =GATSIBO!F37 -> 2731644.9 | C24: =GATSIBO!G37 -> 657787 | D24: =GATSIBO!C43 -> 0 | E24: =GATSIBO!C44 -> 0 | F24: =SUM(B24:C24) -> 3389431.9 | G24: =GATSIBO!C41 -> 0 | H24: =GATSIBO!C39 -> 3389432 | I24: =GATSIBO!C42 -> 0 | J24: =GATSIBO!C40 -> 0
A25: GASHYUSHYA | B25: =GASHYUSHYA!F37 -> 9455958.8 | C25: =GASHYUSHYA!G37 -> 936870 | D25: =GASHYUSHYA!C43 -> 0 | E25: =GASHYUSHYA!C44 -> 0 | F25: =SUM(B25:C25) -> 10392829 | G25: =GASHYUSHYA!C41 -> 0 | H25: =GASHYUSHYA!C39 -> 10582828 | I25: =GASHYUSHYA!C42 -> 0 | J25: =GASHYUSHYA!C40 -> 0
A26: RUTSIRO | B26: =RUTSIRO!F37 -> 0 | C26: =RUTSIRO!G37 -> 0 | D26: =RUTSIRO!C43 -> 0 | E26: =RUTSIRO!C44 -> 0 | F26: =SUM(B26:C26) -> 0 | G26: =RUTSIRO!C41 -> 0 | H26: =RUTSIRO!C39 -> 0 | I26: =RUTSIRO!C42 -> 0 | J26: =RUTSIRO!C40 -> 0
A27: NGORORERO | B27: =NGORORERO!F37 -> 98420.339 | C27: =NGORORERO!G37 -> 13100 | D27: =NGORORERO!C43 -> 0 | E27: =NGORORERO!C44 -> 0 | F27: =SUM(B27:C27) -> 111520.34 | G27: =NGORORERO!C41 -> 0 | H27: =NGORORERO!C39 -> 0 | I27: =NGORORERO!C42 -> 0 | J27: =NGORORERO!C40 -> 0
A28: NYAMASHEKE | B28: =NYAMASHEKE!F37 -> 0 | C28: =NYAMASHEKE!G37 -> 0 | D28: =NYAMASHEKE!C43 -> 0 | E28: =NYAMASHEKE!C44 -> 0 | F28: =SUM(B28:C28) -> 0 | G28: =NYAMASHEKE!C41 -> 0 | H28: =NYAMASHEKE!C39 -> 0 | I28: =NYAMASHEKE!C42 -> 0 | J28: =NYAMASHEKE!C40 -> 0
B29: =SUM(B5:B28) -> 4.1897501e+08 | C29: =SUM(C5:C28) -> 41252191 | D29: =SUM(D5:D28) -> 0 | E29: =SUM(E5:E28) -> 800000 | F29: =SUM(F5:F28) -> 4.602272e+08 | G29: =SUM(G5:G28) -> 0 | H29: =SUM(H5:H28) -> 3.6659322e+08 | I29: =SUM(I5:I28) -> 1645430 | J29: =SUM(J5:J28) -> 6244271
E30: REPORT DESCRIPTION
A31: REPORT SUMMARY
A32: VAT+MSF | C32: =SUM(B29+C29) -> 4.602272e+08
A33: VAT+MSF+FR NOT INVOCED | C33: =SUM(F29,G29) -> 4.602272e+08
A34: MOMO+CASH+BANK+FR NOT INVOICED | C34: =SUM(H29,J29,I29+G29) -> 3.7448292e+08
A35: MS REGIST+MS CONTRIB | C35: =SUM(D29:E29) -> 800000
A36: TOTAL INCOME INVOICED+MSF&MS REGIST | C36: =SUM(H29+I29+J29+C35) -> 3.7528292e+08 | E36: COORDINATOR NAME: Chantal NIYIGENA
A37: TOTAL INCOME | C37: =NYANZA!C45+KIREHE!C45+NYAGATARE!C45+KAYONZA!C45+MUSANZE!C45+MUSANZE!C45+RUBAVU!C45+KARONGI!C45+NYAMAGABE!C45+RUSIZI!C45+HUYE!C45+RUHANGO!C45+MUHANGA!C45+BUGESERA!C45+RWAMAGANA!C45+NYARUGENGE!C45+BISHENYI!C45+GAHANGA!C45+KIMIRONKO!C45+GISOZI!C65+GATSIBO!C45+GASHYUSHYA!C45 -> 3.8754128e+08
A38: RWANDA WOOD VALUE CHAIN ASSOCIATION

Sheet GISOZI
A1: QUANTITY REPORT
A3: MONTHLY REPORT OF JUNE 2026
A5: NAME OF TIMBER | B5: No OF TIMBER | C5: PRICE OF TIMBER | E5: TOTAL COST | F5: TVA | G5: MSF | H5: TVA+MSF
A6: PINUS NINI | B6: 500 | C6: 12000 | E6: =PRODUCT(B6*C6) -> 6000000 | F6: =PRODUCT(E6*18)/118 -> 915254.24 | G6: =PRODUCT(B6*50) -> 25000 | H6: =SUM(F6:G6) -> 940254.24
A7: PINUS | B7: 614 | C7: 10620 | E7: =PRODUCT(B7*C7) -> 6520680 | F7: =PRODUCT(E7*18)/118 -> 994680 | G7: =PRODUCT(B7*50) -> 30700 | H7: =SUM(F7:G7) -> 1025380
A8: PINUS NTOYA | B8: 14938 | C8: 8000 | E8: =PRODUCT(B8*C8) -> 119504000 | F8: =PRODUCT(E8*18)/118 -> 18229424 | G8: =PRODUCT(B8*50) -> 746900 | H8: =SUM(F8:G8) -> 18976324
A9: MADIRIYE NINI | B9: 5038 | C9: 3776 | E9: =PRODUCT(B9*C9) -> 19023488 | F9: =PRODUCT(E9*18)/118 -> 2901888 | G9: =PRODUCT(B9*30) -> 151140 | H9: =SUM(F9:G9) -> 3053028
A10: MADIRIYE NTOYA | B10: 62831 | C10: 2000 | E10: =PRODUCT(B10*C10) -> 125662000 | F10: =PRODUCT(E10*18)/118 -> 19168780 | G10: =PRODUCT(B10*30) -> 1884930 | H10: =SUM(F10:G10) -> 21053710
A11: MADRIEN | B11: 250499 | C11: 2124 | E11: =PRODUCT(B11*C11) -> 532059876 | F11: =PRODUCT(E11*18)/118 -> 81161676 | G11: =PRODUCT(B11*30) -> 7514970 | H11: =SUM(F11:G11) -> 88676646
A12: MADRIEN | B12: 3720 | C12: 3000 | E12: =PRODUCT(B12*C12) -> 11160000 | F12: =PRODUCT(E12*18)/118 -> 1702372.9 | G12: =PRODUCT(B12*30) -> 111600 | H12: =SUM(F12:G12) -> 1813972.9
A13: PLANCHE | B13: 7300 | C13: 1357 | E13: =PRODUCT(B13*C13) -> 9906100 | F13: =PRODUCT(E13*18)/118 -> 1511100 | G13: =PRODUCT(B13*20) -> 146000 | H13: =SUM(F13:G13) -> 1657100
A14: MUNYONGORO | B14: 2971 | C14: 3000 | E14: =PRODUCT(B14*C14) -> 8913000 | F14: =PRODUCT(E14*18)/118 -> 1359610.2 | G14: =PRODUCT(B14*20) -> 59420 | H14: =SUM(F14:G14) -> 1419030.2
A15: Other Timber for Difference Price
A16: NAME OF TIMBER | B16: No OF TIMBER | C16: P/U | D16: MSF | E16: TOTAL COST | F16: VAT | G16: MSF | H16: VTA+MST
A17: INTURUSU | B17: 720 | C17: 2600 | D17: 30 | E17: =PRODUCT(B17*C17) -> 1872000 | F17: =PRODUCT(E17*18)/118 -> 285559.32 | G17: =PRODUCT(B17*D17) -> 21600 | H17: =SUM(F17:G17) -> 307159.32
A18: IBIPANDE BYA PINUS | B18: 2007 | C18: 2000 | D18: 25 | E18: =PRODUCT(B18*C18) -> 4014000 | F18: =PRODUCT(E18*18)/118 -> 612305.08 | G18: =PRODUCT(B18*D18) -> 50175 | H18: =SUM(F18:G18) -> 662480.08
A19: PINUS | B19: 1797 | C19: 5000 | D19: 50 | E19: =PRODUCT(B19*C19) -> 8985000 | F19: =PRODUCT(E19*18)/118 -> 1370593.2 | G19: =PRODUCT(B19*D19) -> 89850 | H19: =SUM(F19:G19) -> 1460443.2
A20: IBIPANDE BY'INTURUSU | B20: 840 | C20: 1500 | D20: 20 | E20: =PRODUCT(B20*C20) -> 1260000 | F20: =PRODUCT(E20*18)/118 -> 192203.39 | G20: =PRODUCT(B20*D20) -> 16800 | H20: =SUM(F20:G20) -> 209003.39
A21: SIPURI | B21: 40 | C21: 8000 | D21: 50 | E21: =PRODUCT(B21*C21) -> 320000 | F21: =PRODUCT(E21*18)/118 -> 48813.559 | G21: =PRODUCT(B21*D21) -> 2000 | H21: =SUM(F21:G21) -> 50813.559
A22: MUNYONGORO | E22: =PRODUCT(B22*C22) -> 0 | F22: =PRODUCT(E22*18)/118 -> 0 | G22: =PRODUCT(B22*D22) -> 0 | H22: =SUM(F22:G22) -> 0
A23: PINUS NINI, | E23: =PRODUCT(B23*C23) -> 0 | F23: =PRODUCT(E23*18)/118 -> 0 | G23: =PRODUCT(B23*D23) -> 0 | H23: =SUM(F23:G23) -> 0
A24: PINUS | B24: 1307 | C24: 6000 | D24: 50 | E24: =PRODUCT(B24*C24) -> 7842000 | F24: =PRODUCT(E24*18)/118 -> 1196237.3 | G24: =PRODUCT(B24*D24) -> 65350 | H24: =SUM(F24:G24) -> 1261587.3
A25: MADRIEN | B25: 400 | C25: 2500 | D25: 30 | E25: =PRODUCT(B25*C25) -> 1000000 | F25: =PRODUCT(E25*18)/118 -> 152542.37 | G25: =PRODUCT(B25*D25) -> 12000 | H25: =SUM(F25:G25) -> 164542.37
A26: PINUS NTOYA | B26: 230 | C26: 4000 | D26: 50 | E26: =PRODUCT(B26*C26) -> 920000 | F26: =PRODUCT(E26*18)/118 -> 140338.98 | G26: =PRODUCT(B26*D26) -> 11500 | H26: =SUM(F26:G26) -> 151838.98
A27: PLANCHET ZA PINUS | B27: 300 | C27: 1770 | D27: 20 | E27: =PRODUCT(B27*C27) -> 531000 | F27: =PRODUCT(E27*18)/118 -> 81000 | G27: =PRODUCT(B27*D27) -> 6000 | H27: =SUM(F27:G27) -> 87000
A28: MADRIEN | B28: 450 | C28: 2596 | D28: 30 | E28: =PRODUCT(B28*C28) -> 1168200 | F28: =PRODUCT(E28*18)/118 -> 178200 | G28: =PRODUCT(B28*D28) -> 13500 | H28: =SUM(F28:G28) -> 191700
A29: MADRIEN | B29: 616 | C29: 3500 | D29: 30 | E29: =PRODUCT(B29*C29) -> 2156000 | F29: =PRODUCT(E29*18)/118 -> 328881.36 | G29: =PRODUCT(B29*D29) -> 18480 | H29: =SUM(F29:G29) -> 347361.36
A30: INTURUSU NTOYA | E30: =PRODUCT(B30*C30) -> 0 | F30: =PRODUCT(E30*18)/118 -> 0 | G30: =PRODUCT(B30*D30) -> 0 | H30: =SUM(F30:G30) -> 0
A31: DECHET | B31: 42 | C31: 10000 | E31: =PRODUCT(B31*C31) -> 420000 | F31: =PRODUCT(E31*18)/118 -> 64067.797 | G31: =PRODUCT(B31*D31) -> 0 | H31: =SUM(F31:G31) -> 64067.797
A32: DECHET | B32: 6 | D32: 5000 | E32: =PRODUCT(B32*C32) -> 0 | F32: =PRODUCT(E32*18)/118 -> 0 | G32: =PRODUCT(B32*D32) -> 30000 | H32: =SUM(F32:G32) -> 30000
A33: MUNYONGORO | E33: =PRODUCT(B33*C33) -> 0 | F33: =PRODUCT(E33*18)/118 -> 0 | G33: =PRODUCT(B33*D33) -> 0 | H33: =SUM(F33:G33) -> 0
A34: MUNYONGORO | E34: =PRODUCT(B34*C34) -> 0 | F34: =PRODUCT(E34*18)/118 -> 0 | G34: =PRODUCT(B34*D34) -> 0 | H34: =SUM(F34:G34) -> 0
A35: OTHER | E35: =PRODUCT(B35*C35) -> 0 | F35: =PRODUCT(E35*18)/118 -> 0 | G35: =PRODUCT(B35*D35) -> 0 | H35: =SUM(F35:G35) -> 0
A36: PINUS | B36: 1087 | C36: 4720 | D36: 50 | E36: =PRODUCT(B36*C36) -> 5130640 | F36: =PRODUCT(E36*18)/118 -> 782640 | G36: =PRODUCT(B36*D36) -> 54350 | H36: =SUM(F36:G36) -> 836990
A37: MUNYONGORO | E37: =PRODUCT(B37*C37) -> 0 | F37: =PRODUCT(E37*18)/118 -> 0 | G37: =PRODUCT(B37*D37) -> 0 | H37: =SUM(F37:G37) -> 0
A38: MADRIEN | E38: =PRODUCT(B38*C38) -> 0 | F38: =PRODUCT(E38*18)/118 -> 0 | G38: =PRODUCT(B38*D38) -> 0 | H38: =SUM(F38:G38) -> 0
A39: IBIPANDE BYA PINUS | E39: =PRODUCT(B39*C39) -> 0 | F39: =PRODUCT(E39*18)/118 -> 0 | G39: =PRODUCT(B39*D39) -> 0 | H39: =SUM(F39:G39) -> 0
A40: PINUS | E40: =PRODUCT(B40*C40) -> 0 | F40: =PRODUCT(E40*18)/118 -> 0 | G40: =PRODUCT(B40*D40) -> 0 | H40: =SUM(F40:G40) -> 0
A41: SIPURE | E41: =PRODUCT(B41*C41) -> 0 | F41: =PRODUCT(E41*18)/118 -> 0 | G41: =PRODUCT(B41*D41) -> 0 | H41: =SUM(F41:G41) -> 0
A42: INTURUSU NTOYA | E42: =PRODUCT(B42*C42) -> 0 | F42: =PRODUCT(E42*18)/118 -> 0 | G42: =PRODUCT(B42*D42) -> 0 | H42: =SUM(F42:G42) -> 0
...

Sheet BISHENYI
A1: QUANTITY REPORT
A3: MONTHLY REPORT OF MAY 2026
A5: NAME OF TIMBER | B5: No OF TIMBER | C5: PRICE OF TIMBER | E5: TOTAL COST | F5: TVA | G5: MSF | H5: TVA+MSF
A6: PINUS NINI | B6: 945 | C6: 7670 | E6: =PRODUCT(B6*C6) -> 7248150 | F6: =PRODUCT(E6*18)/118 -> 1105650 | G6: =PRODUCT(B6*50) -> 47250 | H6: =SUM(F6:G6) -> 1152900
A7: PINUS NTOYA | C7: 7670 | E7: =PRODUCT(B7*C7) -> 0 | F7: =PRODUCT(E7*18)/118 -> 0 | G7: =PRODUCT(B7*50) -> 0 | H7: =SUM(F7:G7) -> 0
A8: PINUS | E8: =PRODUCT(B8*C8) -> 0 | F8: =PRODUCT(E8*18)/118 -> 0 | G8: =PRODUCT(B8*50) -> 0 | H8: =SUM(F8:G8) -> 0
A9: MADIRIYE NINI | B9: 185 | C9: 3776 | E9: =PRODUCT(B9*C9) -> 698560 | F9: =PRODUCT(E9*18)/118 -> 106560 | G9: =PRODUCT(B9*30) -> 5550 | H9: =SUM(F9:G9) -> 112110
A10: MADIRIYE NTOYA | B10: 92166 | C10: 2360 | E10: =PRODUCT(B10*C10) -> 217511760 | F10: =PRODUCT(E10*18)/118 -> 33179760 | G10: =PRODUCT(B10*30) -> 2764980 | H10: =SUM(F10:G10) -> 35944740
A11: MADRIEN | E11: =PRODUCT(B11*C11) -> 0 | F11: =PRODUCT(E11*18)/118 -> 0 | G11: =PRODUCT(B11*30) -> 0 | H11: =SUM(F11:G11) -> 0
A12: MADRIEN | E12: =PRODUCT(B12*C12) -> 0 | F12: =PRODUCT(E12*18)/118 -> 0 | G12: =PRODUCT(B12*30) -> 0 | H12: =SUM(F12:G12) -> 0
A13: PLANCHE | B13: 8400 | C13: 1534 | E13: =PRODUCT(B13*C13) -> 12885600 | F13: =PRODUCT(E13*18)/118 -> 1965600 | G13: =PRODUCT(B13*20) -> 168000 | H13: =SUM(F13:G13) -> 2133600
A14: PLANCHE | E14: =PRODUCT(B14*C14) -> 0 | F14: =PRODUCT(E14*18)/118 -> 0 | G14: =PRODUCT(B14*20) -> 0 | H14: =SUM(F14:G14) -> 0
A15: Other Timber for Difference Price
A16: NAME OF TIMBER | B16: No OF TIMBER | C16: P/U | D16: MSF | E16: TOTAL COST | F16: VAT | G16: MSF | H16: VTA+MST
A17: IBIPANDE BYA PINUS | B17: 750 | C17: 2000 | D17: 50 | E17: =PRODUCT(B17*C17) -> 1500000 | F17: =PRODUCT(E17*18)/118 -> 228813.56 | G17: =PRODUCT(B17*D17) -> 37500 | H17: =SUM(F17:G17) -> 266313.56
A18: DECHET | B18: 14 | C18: 10000 | E18: =PRODUCT(B18*C18) -> 140000 | F18: =PRODUCT(E18*18)/118 -> 21355.932 | G18: =PRODUCT(B18*D18) -> 0 | H18: =SUM(F18:G18) -> 21355.932
A19: DECHET | B19: 2 | D19: 10000 | E19: =PRODUCT(B19*C19) -> 0 | F19: =PRODUCT(E19*18)/118 -> 0 | G19: =PRODUCT(B19*D19) -> 20000 | H19: =SUM(F19:G19) -> 20000
A20: UMUSAVE | E20: =PRODUCT(B20*C20) -> 0 | F20: =PRODUCT(E20*18)/118 -> 0 | G20: =PRODUCT(B20*D20) -> 0 | H20: =SUM(F20:G20) -> 0
A21: OTHER | E21: =PRODUCT(B21*C21) -> 0 | F21: =PRODUCT(E21*18)/118 -> 0 | G21: =PRODUCT(B21*D21) -> 0 | H21: =SUM(F21:G21) -> 0
A22: OTHER | E22: =PRODUCT(B22*C22) -> 0 | F22: =PRODUCT(E22*18)/118 -> 0 | G22: =PRODUCT(B22*D22) -> 0 | H22: =SUM(F22:G22) -> 0
A23: OTHER | E23: =PRODUCT(B23*C23) -> 0 | F23: =PRODUCT(E23*18)/118 -> 0 | G23: =PRODUCT(B23*D23) -> 0 | H23: =SUM(F23:G23) -> 0
A24: OTHER | E24: =PRODUCT(B24*C24) -> 0 | F24: =PRODUCT(E24*18)/118 -> 0 | G24: =PRODUCT(B24*D24) -> 0 | H24: =SUM(F24:G24) -> 0
A25: OTHER | E25: =PRODUCT(B25*C25) -> 0 | F25: =PRODUCT(E25*18)/118 -> 0 | G25: =PRODUCT(B25*D25) -> 0 | H25: =SUM(F25:G25) -> 0
A26: OTHER | E26: =PRODUCT(B26*C26) -> 0 | F26: =PRODUCT(E26*18)/118 -> 0 | G26: =PRODUCT(B26*D26) -> 0 | H26: =SUM(F26:G26) -> 0
A27: OTHER | E27: =PRODUCT(B27*C27) -> 0 | F27: =PRODUCT(E27*18)/118 -> 0 | G27: =PRODUCT(B27*D27) -> 0 | H27: =SUM(F27:G27) -> 0
A28: OTHER | E28: =PRODUCT(B28*C28) -> 0 | F28: =PRODUCT(E28*18)/118 -> 0 | G28: =PRODUCT(B28*D28) -> 0 | H28: =SUM(F28:G28) -> 0
A29: OTHER | E29: =PRODUCT(B29*C29) -> 0 | F29: =PRODUCT(E29*18)/118 -> 0 | G29: =PRODUCT(B29*D29) -> 0 | H29: =SUM(F29:G29) -> 0
A30: OTHER | E30: =PRODUCT(B30*C30) -> 0 | F30: =PRODUCT(E30*18)/118 -> 0 | G30: =PRODUCT(B30*D30) -> 0 | H30: =SUM(F30:G30) -> 0
A31: OTHER | E31: =PRODUCT(B31*C31) -> 0 | F31: =PRODUCT(E31*18)/118 -> 0 | G31: =PRODUCT(B31*D31) -> 0 | H31: =SUM(F31:G31) -> 0
... A36: OTHER | E36: =PRODUCT(B36*C36) -> 0 | F36: =PRODUCT(E36*18)/118 -> 0 | G36: =PRODUCT(B36*D36) -> 0 | H36: =SUM(F36:G36) -> 0
A37: TOTALY | E37: =SUM(E5:E36) -> 239984070 | F37: =SUM(F5:F36) -> 36607739 | G37: =SUM(G5:G36) -> 3043280 | H37: =SUM(H5:H36) -> 39651019
A38: SUMMARY | C38: RWF | E38: NAME | G38: Phone | H38: RWF
A39: TOTAL RWF PAID ON MOMO PAY | C39: 39653064
A40: TOTAL RWF PAID ON CASH
A41: AMOUNT NOT INVOICED
A42: TOTAL RWF DEPPOSITED ON BANK
A43: MEMBERSHIP FEES REGISTRETION
A44: MEMBERSHIP FEES CONTRIBUTION
A45: TOTAL INCOME | C45: =SUM(C39+C40+C41+C42+C43+C44) -> 39653064
A46: TIMBER SUMMARY
...

Sheet RWAMAGANA
A1: QUANTITY REPORT
A3: MONTHLY REPORT OF MAY 2026
A5: NAME OF TIMBER | B5: No OF TIMBER | C5: PRICE OF TIMBER | E5: TOTAL COST | F5: TVA | G5: MSF | H5: TVA+MSF
A6: PINUS NINI | E6: =PRODUCT(B6*C6) -> 0 | F6: =PRODUCT(E6*18)/118 -> 0 | G6: =PRODUCT(B6*50) -> 0 | H6: =SUM(F6:G6) -> 0
A7: PINUS NTOYA | B7: 970 | C7: 5900 | E7: =PRODUCT(B7*C7) -> 5723000 | F7: =PRODUCT(E7*18)/118 -> 873000 | G7: =PRODUCT(B7*50) -> 48500 | H7: =SUM(F7:G7) -> 921500
A8: PINUS | E8: =PRODUCT(B8*C8) -> 0 | F8: =PRODUCT(E8*18)/118 -> 0 | G8: =PRODUCT(B8*50) -> 0 | H8: =SUM(F8:G8) -> 0
A9: MADIRIYE NINI | E9: =PRODUCT(B9*C9) -> 0 | F9: =PRODUCT(E9*18)/118 -> 0 | G9: =PRODUCT(B9*30) -> 0 | H9: =SUM(F9:G9) -> 0
A10: MADIRIYE NTOYA | E10: =PRODUCT(B10*C10) -> 0 | F10: =PRODUCT(E10*18)/118 -> 0 | G10: =PRODUCT(B10*30) -> 0 | H10: =SUM(F10:G10) -> 0
A11: MADRIEN | B11: 36147 | C11: 2124 | E11: =PRODUCT(B11*C11) -> 76776228 | F11: =PRODUCT(E11*18)/118 -> 11711628 | G11: =PRODUCT(B11*30) -> 1084410 | H11: =SUM(F11:G11) -> 12796038
A12: MADRIEN | E12: =PRODUCT(B12*C12) -> 0 | F12: =PRODUCT(E12*18)/118 -> 0 | G12: =PRODUCT(B12*30) -> 0 | H12: =SUM(F12:G12) -> 0
A13: PLANCHE | B13: 1838 | C13: 1357 | E13: =PRODUCT(B13*C13) -> 2494166 | F13: =PRODUCT(E13*18)/118 -> 380466 | G13: =PRODUCT(B13*20) -> 36760 | H13: =SUM(F13:G13) -> 417226
A14: PLANCHE | E14: =PRODUCT(B14*C14) -> 0 | F14: =PRODUCT(E14*18)/118 -> 0 | G14: =PRODUCT(B14*20) -> 0 | H14: =SUM(F14:G14) -> 0
A15: Other Timber for Difference Price
A16: NAME OF TIMBER | B16: No OF TIMBER | C16: P/U | D16: MSF | E16: TOTAL COST | F16: VAT | G16: MSF | H16: VTA+MST
A17: DECHETS | B17: 21 | C17: 10000 | D17: 1331 | E17: =PRODUCT(B17*C17) -> 210000 | F17: =PRODUCT(E17*18)/118 -> 32033.898 | G17: =PRODUCT(B17*D17) -> 27951 | H17: =SUM(F17:G17) -> 59984.898
A18: IBIPANDE | D18: 210 | E18: =PRODUCT(B18*C18) -> 0 | F18: =PRODUCT(E18*18)/118 -> 0 | G18: =PRODUCT(B18*D18) -> 0 | H18: =SUM(F18:G18) -> 0
A19: UMUSAVE | E19: =PRODUCT(B19*C19) -> 0 | F19: =PRODUCT(E19*18)/118 -> 0 | G19: =PRODUCT(B19*D19) -> 0 | H19: =SUM(F19:G19) -> 0
A20: UMUSAVE | E20: =PRODUCT(B20*C20) -> 0 | F20: =PRODUCT(E20*18)/118 -> 0 | G20: =PRODUCT(B20*D20) -> 0 | H20: =SUM(F20:G20) -> 0
A21: GEREVERIYA | B21: 1181 | D21: 210 | E21: =PRODUCT(B21*C21) -> 0 | F21: =PRODUCT(E21*18)/118 -> 0 | G21: =PRODUCT(B21*D21) -> 248010 | H21: =SUM(F21:G21) -> 248010
A22: GEREVERIYA | B22: 50 | C22: 1180 | D22: 30 | E22: =PRODUCT(B22*C22) -> 59000 | F22: =PRODUCT(E22*18)/118 -> 9000 | G22: =PRODUCT(B22*D22) -> 1500 | H22: =SUM(F22:G22) -> 10500
A23: PINUS | B23: 793 | D23: 50 | E23: =PRODUCT(B23*C23) -> 0 | F23: =PRODUCT(E23*18)/118 -> 0 | G23: =PRODUCT(B23*D23) -> 39650 | H23: =SUM(F23:G23) -> 39650
A24: OTHER | E24: =PRODUCT(B24*C24) -> 0 | F24: =PRODUCT(E24*18)/118 -> 0 | G24: =PRODUCT(B24*D24) -> 0 | H24: =SUM(F24:G24) -> 0
A25: OTHER | E25: =PRODUCT(B25*C25) -> 0 | F25: =PRODUCT(E25*18)/118 -> 0 | G25: =PRODUCT(B25*D25) -> 0 | H25: =SUM(F25:G25) -> 0
A26: OTHER | E26: =PRODUCT(B26*C26) -> 0 | F26: =PRODUCT(E26*18)/118 -> 0 | G26: =PRODUCT(B26*D26) -> 0 | H26: =SUM(F26:G26) -> 0
A27: OTHER | E27: =PRODUCT(B27*C27) -> 0 | F27: =PRODUCT(E27*18)/118 -> 0 | G27: =PRODUCT(B27*D27) -> 0 | H27: =SUM(F27:G27) -> 0
A28: OTHER | E28: =PRODUCT(B28*C28) -> 0 | F28: =PRODUCT(E28*18)/118 -> 0 | G28: =PRODUCT(B28*D28) -> 0 | H28: =SUM(F28:G28) -> 0
A29: OTHER | E29: =PRODUCT(B29*C29) -> 0 | F29: =PRODUCT(E29*18)/118 -> 0 | G29: =PRODUCT(B29*D29) -> 0 | H29: =SUM(F29:G29) -> 0
A30: OTHER | E30: =PRODUCT(B30*C30) -> 0 | F30: =PRODUCT(E30*18)/118 -> 0 | G30: =PRODUCT(B30*D30) -> 0 | H30: =SUM(F30:G30) -> 0
A31: OTHER | E31: =PRODUCT(B31*C31) -> 0 | F31: =PRODUCT(E31*18)/118 -> 0 | G31: =PRODUCT(B31*D31) -> 0 | H31: =SUM(F31:G31) -> 0
A32: OTHER | E32: =PRODUCT(B32*C32) -> 0 | F32: =PRODUCT(E32*18)/118 -> 0 | G32: =PRODUCT(B32*D32) -> 0 | H32: =SUM(F32:G32) -> 0
A33: OTHER | E33: =PRODUCT(B33*C33) -> 0 | F33: =PRODUCT(E33*18)/118 -> 0 | G33: =PRODUCT(B33*D33) -> 0 | H33: =SUM(F33:G33) -> 0
A34: OTHER | E34: =PRODUCT(B34*C34) -> 0 | F34: =PRODUCT(E34*18)/118 -> 0 | G34: =PRODUCT(B34*D34) -> 0 | H34: =SUM(F34:G34) -> 0
A35: OTHER | E35: =PRODUCT(B35*C35) -> 0 | F35: =PRODUCT(E35*18)/118 -> 0 | G35: =PRODUCT(B35*D35) -> 0 | H35: =SUM(F35:G35) -> 0
A36: OTHER | E36: =PRODUCT(B36*C36) -> 0 | F36: =PRODUCT(E36*18)/118 -> 0 | G36: =PRODUCT(B36*D36) -> 0 | H36: =SUM(F36:G36) -> 0
A37: TOTALY | E37: =SUM(E5:E36) -> 85262394 | F37: =SUM(F5:F36) -> 13006128 | G37: =SUM(G5:G36) -> 1486781 | H37: =SUM(H5:H36) -> 14492909
A38: SUMMARY | C38: RWF | E38: NAME | G38: Phone | H38: RWF
A39: TOTAL RWF PAID ON MOMO PAY | C39: 14492909
A40: TOTAL RWF PAID ON CASH
A41: AMOUNT NOT INVOICED
A42: TOTAL RWF DEPPOSITED ON BANK
...

Sheet KIMIRONKO
A1: QUANTITY&FINACHIAL REPORT
A3: MONTHLY REPORT OF MAY 2026
A5: NAME OF TIMBER | B5: No OF TIMBER | C5: PRICE OF TIMBER | E5: TOTAL COST | F5: TVA | G5: MSF | H5: TVA+MSF
A6: PINUS NINI | B6: 150 | C6: 12500 | E6: =PRODUCT(B6*C6) -> 1875000 | F6: =PRODUCT(E6*18)/118 -> 286016.95 | G6: =PRODUCT(B6*50) -> 7500 | H6: =SUM(F6:G6) -> 293516.95
A7: PINUS NTOYA | B7: 2892 | C7: 3000 | E7: =PRODUCT(B7*C7) -> 8676000 | F7: =PRODUCT(E7*18)/118 -> 1323457.6 | G7: =PRODUCT(B7*50) -> 144600 | H7: =SUM(F7:G7) -> 1468057.6
A8: PINUS | B8: 1545 | C8: 7670 | E8: =PRODUCT(B8*C8) -> 11850150 | F8: =PRODUCT(E8*18)/118 -> 1807650 | G8: =PRODUCT(B8*50) -> 77250 | H8: =SUM(F8:G8) -> 1884900
A9: MADIRIYE NINI | E9: =PRODUCT(B9*C9) -> 0 | F9: =PRODUCT(E9*18)/118 -> 0 | G9: =PRODUCT(B9*30) -> 0 | H9: =SUM(F9:G9) -> 0
A10: MADIRIYE NTOYA | B10: 120728 | C10: 2124 | E10: =PRODUCT(B10*C10) -> 256426272 | F10: =PRODUCT(E10*18)/118 -> 39115872 | G10: =PRODUCT(B10*30) -> 3621840 | H10: =SUM(F10:G10) -> 42737712
A11: MADRIEN | E11: =PRODUCT(B11*C11) -> 0 | F11: =PRODUCT(E11*18)/118 -> 0 | G11: =PRODUCT(B11*30) -> 0 | H11: =SUM(F11:G11) -> 0
A12: MADRIEN | E12: =PRODUCT(B12*C12) -> 0 | F12: =PRODUCT(E12*18)/118 -> 0 | G12: =PRODUCT(B12*30) -> 0 | H12: =SUM(F12:G12) -> 0
A13: PLANCHE | B13: 6903 | C13: 1357 | E13: =PRODUCT(B13*C13) -> 9367371 | F13: =PRODUCT(E13*18)/118 -> 1428921 | G13: =PRODUCT(B13*20) -> 138060 | H13: =SUM(F13:G13) -> 1566981
A14: PLANCHE | E14: =PRODUCT(B14*C14) -> 0 | F14: =PRODUCT(E14*18)/118 -> 0 | G14: =PRODUCT(B14*20) -> 0 | H14: =SUM(F14:G14) -> 0
A15: Other Timber for Difference Price
A16: NAME OF TIMBER | B16: No OF TIMBER | C16: P/U | D16: MSF | E16: TOTAL COST | F16: VAT | G16: MSF | H16: VTA+MST
A17: IBIPANDE | E17: =PRODUCT(B17*C17) -> 0 | F17: =PRODUCT(E17*18)/118 -> 0 | G17: =PRODUCT(B17*D17) -> 0 | H17: =SUM(F17:G17) -> 0
A18: IBIPANDE | E18: =PRODUCT(B18*C18) -> 0 | F18: =PRODUCT(E18*18)/118 -> 0 | G18: =PRODUCT(B18*D18) -> 0 | H18: =SUM(F18:G18) -> 0
A19: UMUSAVE | E19: =PRODUCT(B19*C19) -> 0 | F19: =PRODUCT(E19*18)/118 -> 0 | G19: =PRODUCT(B19*D19) -> 0 | H19: =SUM(F19:G19) -> 0
A20: UMUSAVE | E20: =PRODUCT(B20*C20) -> 0 | F20: =PRODUCT(E20*18)/118 -> 0 | G20: =PRODUCT(B20*D20) -> 0 | H20: =SUM(F20:G20) -> 0
A21: OTHER | E21: =PRODUCT(B21*C21) -> 0 | F21: =PRODUCT(E21*18)/118 -> 0 | G21: =PRODUCT(B21*D21) -> 0 | H21: =SUM(F21:G21) -> 0
A22: OTHER | E22: =PRODUCT(B22*C22) -> 0 | F22: =PRODUCT(E22*18)/118 -> 0 | G22: =PRODUCT(B22*D22) -> 0 | H22: =SUM(F22:G22) -> 0
A23: OTHER | E23: =PRODUCT(B23*C23) -> 0 | F23: =PRODUCT(E23*18)/118 -> 0 | G23: =PRODUCT(B23*D23) -> 0 | H23: =SUM(F23:G23) -> 0
A24: OTHER | E24: =PRODUCT(B24*C24) -> 0 | F24: =PRODUCT(E24*18)/118 -> 0 | G24: =PRODUCT(B24*D24) -> 0 | H24: =SUM(F24:G24) -> 0
A25: OTHER | E25: =PRODUCT(B25*C25) -> 0 | F25: =PRODUCT(E25*18)/118 -> 0 | G25: =PRODUCT(B25*D25) -> 0 | H25: =SUM(F25:G25) -> 0
A26: OTHER | E26: =PRODUCT(B26*C26) -> 0 | F26: =PRODUCT(E26*18)/118 -> 0 | G26: =PRODUCT(B26*D26) -> 0 | H26: =SUM(F26:G26) -> 0
A27: OTHER | E27: =PRODUCT(B27*C27) -> 0 | F27: =PRODUCT(E27*18)/118 -> 0 | G27: =PRODUCT(B27*D27) -> 0 | H27: =SUM(F27:G27) -> 0
A28: OTHER | E28: =PRODUCT(B28*C28) -> 0 | F28: =PRODUCT(E28*18)/118 -> 0 | G28: =PRODUCT(B28*D28) -> 0 | H28: =SUM(F28:G28) -> 0
... A36: OTHER | E36: =PRODUCT(B36*C36) -> 0 | F36: =PRODUCT(E36*18)/118 -> 0 | G36: =PRODUCT(B36*D36) -> 0 | H36: =SUM(F36:G36) -> 0
A37: TOTALY | E37: =SUM(E5:E36) -> 288194793 | F37: =SUM(F5:F36) -> 43961918 | G37: =SUM(G5:G36) -> 3989250 | H37: =SUM(H5:H36) -> 47951168
A38: SUMMARY | C38: RWF | E38: NAME | G38: Phone | H38: RWF
A39: TOTAL RWF PAID ON MOMO PAY
A40: TOTAL RWF PAID ON CASH
A41: AMOUNT NOT INVOICED
A42: TOTAL RWF DEPPOSITED ON BANK
A43: MEMBERSHIP FEES REGISTRETION
A44: MEMBERSHIP FEES CONTRIBUTION
A45: TOTAL INCOME | C45: =SUM(C39+C40+C41+C42+C43+C44) -> 0
A46: TIMBER SUMMARY
A48: REPORT SUMMARY | C48: TIMBER TYPE | E48: NUMBER OF QUANTITY
C49: INTURUSU | E49: =SUM(B9:B12) -> 120728
C50: PINUS | E50: =SUM(B6:B8) -> 4587
...

Sheet GAHANGA
A1: QUANTITY REPORT
A3: MONTHLY REPORT OF MAY 2026
A5: NAME OF TIMBER | B5: No OF TIMBER | C5: PRICE OF TIMBER | E5: TOTAL COST | F5: TVA | G5: MSF | H5: TVA+MSF
A6: PINUS NINI | E6: =PRODUCT(B6*C6) -> 0 | F6: =PRODUCT(E6*18)/118 -> 0 | G6: =PRODUCT(B6*50) -> 0 | H6: =SUM(F6:G6) -> 0
A7: PINUS NTOYA | B7: 1905 | C7: 7670 | E7: =PRODUCT(B7*C7) -> 14611350 | F7: =PRODUCT(E7*18)/118 -> 2228850 | G7: =PRODUCT(B7*50) -> 95250 | H7: =SUM(F7:G7) -> 2324100
A8: PINUS | B8: 264 | C8: 8000 | E8: =PRODUCT(B8*C8) -> 2112000 | F8: =PRODUCT(E8*18)/118 -> 322169.49 | G8: =PRODUCT(B8*50) -> 13200 | H8: =SUM(F8:G8) -> 335369.49
A9: MADIRIYE NINI | E9: =PRODUCT(B9*C9) -> 0 | F9: =PRODUCT(E9*18)/118 -> 0 | G9: =PRODUCT(B9*30) -> 0 | H9: =SUM(F9:G9) -> 0
A10: MADIRIYE NTOYA | B10: 84966 | C10: 2124 | E10: =PRODUCT(B10*C10) -> 180467784 | F10: =PRODUCT(E10*18)/118 -> 27528984 | G10: =PRODUCT(B10*30) -> 2548980 | H10: =SUM(F10:G10) -> 30077964
A11: MADRIEN | B11: 200 | C11: 3500 | E11: =PRODUCT(B11*C11) -> 700000 | F11: =PRODUCT(E11*18)/118 -> 106779.66 | G11: =PRODUCT(B11*30) -> 6000 | H11: =SUM(F11:G11) -> 112779.66
A12: MADRIEN | E12: =PRODUCT(B12*C12) -> 0 | F12: =PRODUCT(E12*18)/118 -> 0 | G12: =PRODUCT(B12*30) -> 0 | H12: =SUM(F12:G12) -> 0
A13: PLANCHE | B13: 3400 | C13: 1357 | E13: =PRODUCT(B13*C13) -> 4613800 | F13: =PRODUCT(E13*18)/118 -> 703800 | G13: =PRODUCT(B13*20) -> 68000 | H13: =SUM(F13:G13) -> 771800
A14: PLANCHE | E14: =PRODUCT(B14*C14) -> 0 | F14: =PRODUCT(E14*18)/118 -> 0 | G14: =PRODUCT(B14*20) -> 0 | H14: =SUM(F14:G14) -> 0
A15: Other Timber for Difference Price
A16: NAME OF TIMBER | B16: No OF TIMBER | C16: P/U | D16: MSF | E16: TOTAL COST | F16: VAT | G16: MSF | H16: VTA+MST
A17: IBIPANDE | B17: 300 | C17: 4000 | D17: 50 | E17: =PRODUCT(B17*C17) -> 1200000 | F17: =PRODUCT(E17*18)/118 -> 183050.85 | G17: =PRODUCT(B17*D17) -> 15000 | H17: =SUM(F17:G17) -> 198050.85
A18: IBIPANDE | B18: 400 | C18: 2000 | D18: 50 | E18: =PRODUCT(B18*C18) -> 800000 | F18: =PRODUCT(E18*18)/118 -> 122033.9 | G18: =PRODUCT(B18*D18) -> 20000 | H18: =SUM(F18:G18) -> 142033.9
A19: UMUSAVE | B19: 371 | C19: 19500 | D19: 50 | E19: =PRODUCT(B19*C19) -> 7234500 | F19: =PRODUCT(E19*18)/118 -> 1103567.8 | G19: =PRODUCT(B19*D19) -> 18550 | H19: =SUM(F19:G19) -> 1122117.8
A20: UMUSAVE | B20: 111 | C20: 7670 | D20: 50 | E20: =PRODUCT(B20*C20) -> 851370 | F20: =PRODUCT(E20*18)/118 -> 129870 | G20: =PRODUCT(B20*D20) -> 5550 | H20: =SUM(F20:G20) -> 135420
A21: OTHER | E21: =PRODUCT(B21*C21) -> 0 | F21: =PRODUCT(E21*18)/118 -> 0 | G21: =PRODUCT(B21*D21) -> 0 | H21: =SUM(F21:G21) -> 0
A22: OTHER | E22: =PRODUCT(B22*C22) -> 0 | F22: =PRODUCT(E22*18)/118 -> 0 | G22: =PRODUCT(B22*D22) -> 0 | H22: =SUM(F22:G22) -> 0
A23: OTHER | E23: =PRODUCT(B23*C23) -> 0 | F23: =PRODUCT(E23*18)/118 -> 0 | G23: =PRODUCT(B23*D23) -> 0 | H23: =SUM(F23:G23) -> 0
A24: OTHER | E24: =PRODUCT(B24*C24) -> 0 | F24: =PRODUCT(E24*18)/118 -> 0 | G24: =PRODUCT(B24*D24) -> 0 | H24: =SUM(F24:G24) -> 0
A25: OTHER | E25: =PRODUCT(B25*C25) -> 0 | F25: =PRODUCT(E25*18)/118 -> 0 | G25: =PRODUCT(B25*D25) -> 0 | H25: =SUM(F25:G25) -> 0
A26: OTHER | E26: =PRODUCT(B26*C26) -> 0 | F26: =PRODUCT(E26*18)/118 -> 0 | G26: =PRODUCT(B26*D26) -> 0 | H26: =SUM(F26:G26) -> 0
A27: OTHER | E27: =PRODUCT(B27*C27) -> 0 | F27: =PRODUCT(E27*18)/118 -> 0 | G27: =PRODUCT(B27*D27) -> 0 | H27: =SUM(F27:G27) -> 0
A28: OTHER | E28: =PRODUCT(B28*C28) -> 0 | F28: =PRODUCT(E28*18)/118 -> 0 | G28: =PRODUCT(B28*D28) -> 0 | H28: =SUM(F28:G28) -> 0
A29: OTHER | E29: =PRODUCT(B29*C29) -> 0 | F29: =PRODUCT(E29*18)/118 -> 0 | G29: =PRODUCT(B29*D29) -> 0 | H29: =SUM(F29:G29) -> 0
A30: OTHER | E30: =PRODUCT(B30*C30) -> 0 | F30: =PRODUCT(E30*18)/118 -> 0 | G30: =PRODUCT(B30*D30) -> 0 | H30: =SUM(F30:G30) -> 0
A31: OTHER | E31: =PRODUCT(B31*C31) -> 0 | F31: =PRODUCT(E31*18)/118 -> 0 | G31: =PRODUCT(B31*D31) -> 0 | H31: =SUM(F31:G31) -> 0
A32: OTHER | E32: =PRODUCT(B32*C32) -> 0 | F32: =PRODUCT(E32*18)/118 -> 0 | G32: =PRODUCT(B32*D32) -> 0 | H32: =SUM(F32:G32) -> 0
... A36: OTHER | E36: =PRODUCT(B36*C36) -> 0 | F36: =PRODUCT(E36*18)/118 -> 0 | G36: =PRODUCT(B36*D36) -> 0 | H36: =SUM(F36:G36) -> 0
A37: TOTALY | E37: =SUM(E5:E36) -> 212590804 | F37: =SUM(F5:F36) -> 32429106 | G37: =SUM(G5:G36) -> 2790530 | H37: =SUM(H5:H36) -> 35219636
A38: SUMMARY | C38: RWF | E38: NAME | G38: Phone | H38: RWF
A39: TOTAL RWF PAID ON MOMO PAY | C39: 35219636
A40: TOTAL RWF PAID ON CASH
A41: AMOUNT NOT INVOICED
A42: TOTAL RWF DEPPOSITED ON BANK
A43: MEMBERSHIP FEES REGISTRETION
A44: MEMBERSHIP FEES CONTRIBUTION
A45: TOTAL INCOME | C45: =SUM(C39+C40+C41+C42+C43+C44) -> 35219636
...

Sheet BUGESERA
A1: QUANTITY REPORT
A3: MONTHLY REPORT OF MAY 2026
A5: NAME OF TIMBER | B5: No OF TIMBER | C5: PRICE OF TIMBER | E5: TOTAL COST | F5: TVA | G5: MSF | H5: TVA+MSF
A6: PINUS NINI | E6: =PRODUCT(B6*C6) -> 0 | F6: =PRODUCT(E6*18)/118 -> 0 | G6: =PRODUCT(B6*50) -> 0 | H6: =SUM(F6:G6) -> 0
A7: PINUS NTOYA | B7: 1490 | C7: 4720 | E7: =PRODUCT(B7*C7) -> 7032800 | F7: =PRODUCT(E7*18)/118 -> 1072800 | G7: =PRODUCT(B7*50) -> 74500 | H7: =SUM(F7:G7) -> 1147300
A8: PINUS | E8: =PRODUCT(B8*C8) -> 0 | F8: =PRODUCT(E8*18)/118 -> 0 | G8: =PRODUCT(B8*50) -> 0 | H8: =SUM(F8:G8) -> 0
A9: MADIRIYE NINI | E9: =PRODUCT(B9*C9) -> 0 | F9: =PRODUCT(E9*18)/118 -> 0 | G9: =PRODUCT(B9*30) -> 0 | H9: =SUM(F9:G9) -> 0
A10: MADIRIYE NTOYA | B10: 115795 | C10: 2124 | E10: =PRODUCT(B10*C10) -> 245948580 | F10: =PRODUCT(E10*18)/118 -> 37517580 | G10: =PRODUCT(B10*30) -> 3473850 | H10: =SUM(F10:G10) -> 40991430
A11: MADRIEN | E11: =PRODUCT(B11*C11) -> 0 | F11: =PRODUCT(E11*18)/118 -> 0 | G11: =PRODUCT(B11*30) -> 0 | H11: =SUM(F11:G11) -> 0
A12: MADRIEN | E12: =PRODUCT(B12*C12) -> 0 | F12: =PRODUCT(E12*18)/118 -> 0 | G12: =PRODUCT(B12*30) -> 0 | H12: =SUM(F12:G12) -> 0
A13: PLANCHE | B13: 23254 | C13: 1357 | E13: =PRODUCT(B13*C13) -> 31555678 | F13: =PRODUCT(E13*18)/118 -> 4813578 | G13: =PRODUCT(B13*20) -> 465080 | H13: =SUM(F13:G13) -> 5278658
A14: PLANCHE | E14: =PRODUCT(B14*C14) -> 0 | F14: =PRODUCT(E14*18)/118 -> 0 | G14: =PRODUCT(B14*20) -> 0 | H14: =SUM(F14:G14) -> 0
A15: Other Timber for Difference Price
A16: NAME OF TIMBER | B16: No OF TIMBER | C16: P/U | D16: MSF | E16: TOTAL COST | F16: VAT | G16: MSF | H16: VTA+MST
A17: IBIPANDE BYA PINUS | B17: 90 | C17: 2006 | D17: 30 | E17: =PRODUCT(B17*C17) -> 180540 | F17: =PRODUCT(E17*18)/118 -> 27540 | G17: =PRODUCT(B17*D17) -> 2700 | H17: =SUM(F17:G17) -> 30240
A18: IBIPANDE BYA CEDERERA | B18: 118 | C18: 1298 | D18: 30 | E18: =PRODUCT(B18*C18) -> 153164 | F18: =PRODUCT(E18*18)/118 -> 23364 | G18: =PRODUCT(B18*D18) -> 3540 | H18: =SUM(F18:G18) -> 26904
A19: INTURUSU NINI | B19: 1203 | C19: 3304 | D19: 40 | E19: =PRODUCT(B19*C19) -> 3974712 | F19: =PRODUCT(E19*18)/118 -> 606312 | G19: =PRODUCT(B19*D19) -> 48120 | H19: =SUM(F19:G19) -> 654432
A20: UMUSAVE | E20: =PRODUCT(B20*C20) -> 0 | F20: =PRODUCT(E20*18)/118 -> 0 | G20: =PRODUCT(B20*D20) -> 0 | H20: =SUM(F20:G20) -> 0
A21: OTHER | D21: 10000 | E21: =PRODUCT(B21*C21) -> 0 | F21: =PRODUCT(E21*18)/118 -> 0 | G21: =PRODUCT(B21*D21) -> 0 | H21: =SUM(F21:G21) -> 0
A22: OTHER | E22: =PRODUCT(B22*C22) -> 0 | F22: =PRODUCT(E22*18)/118 -> 0 | G22: =PRODUCT(B22*D22) -> 0 | H22: =SUM(F22:G22) -> 0
A23: OTHER | E23: =PRODUCT(B23*C23) -> 0 | F23: =PRODUCT(E23*18)/118 -> 0 | G23: =PRODUCT(B23*D23) -> 0 | H23: =SUM(F23:G23) -> 0
A24: OTHER | E24: =PRODUCT(B24*C24) -> 0 | F24: =PRODUCT(E24*18)/118 -> 0 | G24: =PRODUCT(B24*D24) -> 0 | H24: =SUM(F24:G24) -> 0
A25: OTHER | E25: =PRODUCT(B25*C25) -> 0 | F25: =PRODUCT(E25*18)/118 -> 0 | G25: =PRODUCT(B25*D25) -> 0 | H25: =SUM(F25:G25) -> 0
A26: OTHER | E26: =PRODUCT(B26*C26) -> 0 | F26: =PRODUCT(E26*18)/118 -> 0 | G26: =PRODUCT(B26*D26) -> 0 | H26: =SUM(F26:G26) -> 0
A27: OTHER | E27: =PRODUCT(B27*C27) -> 0 | F27: =PRODUCT(E27*18)/118 -> 0 | G27: =PRODUCT(B27*D27) -> 0 | H27: =SUM(F27:G27) -> 0
A28: OTHER | E28: =PRODUCT(B28*C28) -> 0 | F28: =PRODUCT(E28*18)/118 -> 0 | G28: =PRODUCT(B28*D28) -> 0 | H28: =SUM(F28:G28) -> 0
A29: OTHER | E29: =PRODUCT(B29*C29) -> 0 | F29: =PRODUCT(E29*18)/118 -> 0 | G29: =PRODUCT(B29*D29) -> 0 | H29: =SUM(F29:G29) -> 0
A30: OTHER | E30: =PRODUCT(B30*C30) -> 0 | F30: =PRODUCT(E30*18)/118 -> 0 | G30: =PRODUCT(B30*D30) -> 0 | H30: =SUM(F30:G30) -> 0
A31: OTHER | E31: =PRODUCT(B31*C31) -> 0 | F31: =PRODUCT(E31*18)/118 -> 0 | G31: =PRODUCT(B31*D31) -> 0 | H31: =SUM(F31:G31) -> 0
A32: OTHER | E32: =PRODUCT(B32*C32) -> 0 | F32: =PRODUCT(E32*18)/118 -> 0 | G32: =PRODUCT(B32*D32) -> 0 | H32: =SUM(F32:G32) -> 0
A33: OTHER | E33: =PRODUCT(B33*C33) -> 0 | F33: =PRODUCT(E33*18)/118 -> 0 | G33: =PRODUCT(B33*D33) -> 0 | H33: =SUM(F33:G33) -> 0
... A36: OTHER | E36: =PRODUCT(B36*C36) -> 0 | F36: =PRODUCT(E36*18)/118 -> 0 | G36: =PRODUCT(B36*D36) -> 0 | H36: =SUM(F36:G36) -> 0
A37: TOTALY | E37: =SUM(E5:E36) -> 288845474 | F37: =SUM(F5:F36) -> 44061174 | G37: =SUM(G5:G36) -> 4067790 | H37: =SUM(H5:H36) -> 48128964
A38: SUMMARY | C38: RWF | E38: NAME | G38: Phone | H38: RWF
A39: TOTAL RWF PAID ON MOMO PAY | C39: 45442312
A40: TOTAL RWF PAID ON CASH | C40: 2686652
A41: AMOUNT NOT INVOICED
A42: TOTAL RWF DEPPOSITED ON BANK
A43: MEMBERSHIP FEES REGISTRETION
A44: MEMBERSHIP FEES CONTRIBUTION
...

Sheet NYARUGENGE
A1: QUANTITY REPORT
A3: MONTHLY REPORT OF JUNE 2026
A5: NAME OF TIMBER | B5: No OF TIMBER | C5: PRICE OF TIMBER | E5: TOTAL COST | F5: TVA | G5: MSF | H5: TVA+MSF
A6: PINUS NINI | E6: =PRODUCT(B6*C6) -> 0 | F6: =PRODUCT(E6*18)/118 -> 0 | G6: =PRODUCT(B6*50) -> 0 | H6: =SUM(F6:G6) -> 0
A7: PINUS NTOYA | E7: =PRODUCT(B7*C7) -> 0 | F7: =PRODUCT(E7*18)/118 -> 0 | G7: =PRODUCT(B7*50) -> 0 | H7: =SUM(F7:G7) -> 0
A8: PINUS | B8: 350 | C8: 7670 | E8: =PRODUCT(B8*C8) -> 2684500 | F8: =PRODUCT(E8*18)/118 -> 409500 | G8: =PRODUCT(B8*50) -> 17500 | H8: =SUM(F8:G8) -> 427000
A9: MADIRIYE NINI | E9: =PRODUCT(B9*C9) -> 0 | F9: =PRODUCT(E9*18)/118 -> 0 | G9: =PRODUCT(B9*30) -> 0 | H9: =SUM(F9:G9) -> 0
A10: MADIRIYE NTOYA | B10: 46530 | C10: 2124 | E10: =PRODUCT(B10*C10) -> 98829720 | F10: =PRODUCT(E10*18)/118 -> 15075720 | G10: =PRODUCT(B10*30) -> 1395900 | H10: =SUM(F10:G10) -> 16471620
A11: MADRIEN | E11: =PRODUCT(B11*C11) -> 0 | F11: =PRODUCT(E11*18)/118 -> 0 | G11: =PRODUCT(B11*30) -> 0 | H11: =SUM(F11:G11) -> 0
A12: MADRIEN | E12: =PRODUCT(B12*C12) -> 0 | F12: =PRODUCT(E12*18)/118 -> 0 | G12: =PRODUCT(B12*30) -> 0 | H12: =SUM(F12:G12) -> 0
A13: PLANCHE | B13: 3750 | C13: 1357 | E13: =PRODUCT(B13*C13) -> 5088750 | F13: =PRODUCT(E13*18)/118 -> 776250 | G13: =PRODUCT(B13*20) -> 75000 | H13: =SUM(F13:G13) -> 851250
A14: PLANCHE | E14: =PRODUCT(B14*C14) -> 0 | F14: =PRODUCT(E14*18)/118 -> 0 | G14: =PRODUCT(B14*20) -> 0 | H14: =SUM(F14:G14) -> 0
A15: Other Timber for Difference Price
A16: NAME OF TIMBER | B16: No OF TIMBER | C16: P/U | D16: MSF | E16: TOTAL COST | F16: VAT | G16: MSF | H16: VTA+MST
A17: IBIPANDE | E17: =PRODUCT(B17*C17) -> 0 | F17: =PRODUCT(E17*18)/118 -> 0 | G17: =PRODUCT(B17*D17) -> 0 | H17: =SUM(F17:G17) -> 0
A18: IBIPANDE | E18: =PRODUCT(B18*C18) -> 0 | F18: =PRODUCT(E18*18)/118 -> 0 | G18: =PRODUCT(B18*D18) -> 0 | H18: =SUM(F18:G18) -> 0
A19: UMUSAVE | E19: =PRODUCT(B19*C19) -> 0 | F19: =PRODUCT(E19*18)/118 -> 0 | G19: =PRODUCT(B19*D19) -> 0 | H19: =SUM(F19:G19) -> 0
A20: UMUSAVE | E20: =PRODUCT(B20*C20) -> 0 | F20: =PRODUCT(E20*18)/118 -> 0 | G20: =PRODUCT(B20*D20) -> 0 | H20: =SUM(F20:G20) -> 0
A21: OTHER | E21: =PRODUCT(B21*C21) -> 0 | F21: =PRODUCT(E21*18)/118 -> 0 | G21: =PRODUCT(B21*D21) -> 0 | H21: =SUM(F21:G21) -> 0
A22: OTHER | E22: =PRODUCT(B22*C22) -> 0 | F22: =PRODUCT(E22*18)/118 -> 0 | G22: =PRODUCT(B22*D22) -> 0 | H22: =SUM(F22:G22) -> 0
A23: OTHER | E23: =PRODUCT(B23*C23) -> 0 | F23: =PRODUCT(E23*18)/118 -> 0 | G23: =PRODUCT(B23*D23) -> 0 | H23: =SUM(F23:G23) -> 0
A24: OTHER | E24: =PRODUCT(B24*C24) -> 0 | F24: =PRODUCT(E24*18)/118 -> 0 | G24: =PRODUCT(B24*D24) -> 0 | H24: =SUM(F24:G24) -> 0
A25: OTHER | E25: =PRODUCT(B25*C25) -> 0 | F25: =PRODUCT(E25*18)/118 -> 0 | G25: =PRODUCT(B25*D25) -> 0 | H25: =SUM(F25:G25) -> 0
A26: OTHER | E26: =PRODUCT(B26*C26) -> 0 | F26: =PRODUCT(E26*18)/118 -> 0 | G26: =PRODUCT(B26*D26) -> 0 | H26: =SUM(F26:G26) -> 0
A27: OTHER | E27: =PRODUCT(B27*C27) -> 0 | F27: =PRODUCT(E27*18)/118 -> 0 | G27: =PRODUCT(B27*D27) -> 0 | H27: =SUM(F27:G27) -> 0
A28: OTHER | E28: =PRODUCT(B28*C28) -> 0 | F28: =PRODUCT(E28*18)/118 -> 0 | G28: =PRODUCT(B28*D28) -> 0 | H28: =SUM(F28:G28) -> 0
... A36: OTHER | E36: =PRODUCT(B36*C36) -> 0 | F36: =PRODUCT(E36*18)/118 -> 0 | G36: =PRODUCT(B36*D36) -> 0 | H36: =SUM(F36:G36) -> 0
A37: TOTALY | E37: =SUM(E5:E36) -> 106602970 | F37: =SUM(F5:F36) -> 16261470 | G37: =SUM(G5:G36) -> 1488400 | H37: =SUM(H5:H36) -> 17749870
A38: SUMMARY | C38: RWF | E38: NAME | G38: Phone | H38: RWF
A39: TOTAL RWF PAID ON MOMO PAY | C39: 17749870
A40: TOTAL RWF PAID ON CASH
A41: AMOUNT NOT INVOICED
A42: TOTAL RWF DEPPOSITED ON BANK
A43: MEMBERSHIP FEES REGISTRETION
A44: MEMBERSHIP FEES CONTRIBUTION
A45: TOTAL INCOME | C45: =SUM(C39+C40+C41+C42+C43+C44) -> 17749870
A46: TIMBER SUMMARY
A48: REPORT SUMMARY | C48: TIMBER TYPE | E48: NUMBER OF QUANTITY
C49: INTURUSU | E49: =SUM(B9:B12) -> 46530
C50: PINUS | E50: =SUM(B6:B8) -> 350
...

Sheet MUHANGA
A1: QUANTITY REPORT
A3: MONTHLY REPORT OF MAY 2026
A5: NAME OF TIMBER | B5: No OF TIMBER | C5: PRICE OF TIMBER | E5: TOTAL COST | F5: TVA | G5: MSF | H5: TVA+MSF
A6: PINUS NINI | E6: =PRODUCT(B6*C6) -> 0 | F6: =PRODUCT(E6*18)/118 -> 0 | G6: =PRODUCT(B6*50) -> 0 | H6: =SUM(F6:G6) -> 0
A7: PINUS NTOYA | B7: 253 | C7: 7670 | E7: =PRODUCT(B7*C7) -> 1940510 | F7: =PRODUCT(E7*18)/118 -> 296010 | G7: =PRODUCT(B7*50) -> 12650 | H7: =SUM(F7:G7) -> 308660
A8: PINUS | E8: =PRODUCT(B8*C8) -> 0 | F8: =PRODUCT(E8*18)/118 -> 0 | G8: =PRODUCT(B8*50) -> 0 | H8: =SUM(F8:G8) -> 0
A9: MADIRIYE NINI | E9: =PRODUCT(B9*C9) -> 0 | F9: =PRODUCT(E9*18)/118 -> 0 | G9: =PRODUCT(B9*30) -> 0 | H9: =SUM(F9:G9) -> 0
A10: MADIRIYE NTOYA | B10: 6067 | C10: 2200 | E10: =PRODUCT(B10*C10) -> 13347400 | F10: =PRODUCT(E10*18)/118 -> 2036044.1 | G10: =PRODUCT(B10*30) -> 182010 | H10: =SUM(F10:G10) -> 2218054.1
A11: MADRIEN | B11: 22736 | C11: 2596 | E11: =PRODUCT(B11*C11) -> 59022656 | F11: =PRODUCT(E11*18)/118 -> 9003456 | G11: =PRODUCT(B11*30) -> 682080 | H11: =SUM(F11:G11) -> 9685536
A12: MADRIEN | B12: 1350 | C12: 2500 | E12: =PRODUCT(B12*C12) -> 3375000 | F12: =PRODUCT(E12*18)/118 -> 514830.51 | G12: =PRODUCT(B12*30) -> 40500 | H12: =SUM(F12:G12) -> 555330.51
A13: PLANCHE | B13: 1608 | C13: 1416 | E13: =PRODUCT(B13*C13) -> 2276928 | F13: =PRODUCT(E13*18)/118 -> 347328 | G13: =PRODUCT(B13*20) -> 32160 | H13: =SUM(F13:G13) -> 379488
A14: PLANCHE | B14: 400 | C14: 1200 | E14: =PRODUCT(B14*C14) -> 480000 | F14: =PRODUCT(E14*18)/118 -> 73220.339 | G14: =PRODUCT(B14*20) -> 8000 | H14: =SUM(F14:G14) -> 81220.339
A15: Other Timber for Difference Price
A16: NAME OF TIMBER | B16: No OF TIMBER | C16: P/U | D16: MSF | E16: TOTAL COST | F16: VAT | G16: MSF | H16: VTA+MST
A17: IBIPANDE | B17: 19894 | C17: 1180 | D17: 20 | E17: =PRODUCT(B17*C17) -> 23474920 | F17: =PRODUCT(E17*18)/118 -> 3580920 | G17: =PRODUCT(B17*D17) -> 397880 | H17: =SUM(F17:G17) -> 3978800
A18: MADRIEN NINI | B18: 200 | C18: 4000 | D18: 50 | E18: =PRODUCT(B18*C18) -> 800000 | F18: =PRODUCT(E18*18)/118 -> 122033.9 | G18: =PRODUCT(B18*D18) -> 10000 | H18: =SUM(F18:G18) -> 132033.9
A19: IBIPANDE BYA PINUS | B19: 315 | C19: 2360 | D19: 50 | E19: =PRODUCT(B19*C19) -> 743400 | F19: =PRODUCT(E19*18)/118 -> 113400 | G19: =PRODUCT(B19*D19) -> 15750 | H19: =SUM(F19:G19) -> 129150
A20: UMUSAVE | E20: =PRODUCT(B20*C20) -> 0 | F20: =PRODUCT(E20*18)/118 -> 0 | G20: =PRODUCT(B20*D20) -> 0 | H20: =SUM(F20:G20) -> 0
A21: OTHER | E21: =PRODUCT(B21*C21) -> 0 | F21: =PRODUCT(E21*18)/118 -> 0 | G21: =PRODUCT(B21*D21) -> 0 | H21: =SUM(F21:G21) -> 0
A22: OTHER | E22: =PRODUCT(B22*C22) -> 0 | F22: =PRODUCT(E22*18)/118 -> 0 | G22: =PRODUCT(B22*D22) -> 0 | H22: =SUM(F22:G22) -> 0
A23: OTHER | E23: =PRODUCT(B23*C23) -> 0 | F23: =PRODUCT(E23*18)/118 -> 0 | G23: =PRODUCT(B23*D23) -> 0 | H23: =SUM(F23:G23) -> 0
A24: OTHER | E24: =PRODUCT(B24*C24) -> 0 | F24: =PRODUCT(E24*18)/118 -> 0 | G24: =PRODUCT(B24*D24) -> 0 | H24: =SUM(F24:G24) -> 0
A25: OTHER | E25: =PRODUCT(B25*C25) -> 0 | F25: =PRODUCT(E25*18)/118 -> 0 | G25: =PRODUCT(B25*D25) -> 0 | H25: =SUM(F25:G25) -> 0
A26: OTHER | E26: =PRODUCT(B26*C26) -> 0 | F26: =PRODUCT(E26*18)/118 -> 0 | G26: =PRODUCT(B26*D26) -> 0 | H26: =SUM(F26:G26) -> 0
A27: OTHER | E27: =PRODUCT(B27*C27) -> 0 | F27: =PRODUCT(E27*18)/118 -> 0 | G27: =PRODUCT(B27*D27) -> 0 | H27: =SUM(F27:G27) -> 0
A28: OTHER | E28: =PRODUCT(B28*C28) -> 0 | F28: =PRODUCT(E28*18)/118 -> 0 | G28: =PRODUCT(B28*D28) -> 0 | H28: =SUM(F28:G28) -> 0
A29: OTHER | E29: =PRODUCT(B29*C29) -> 0 | F29: =PRODUCT(E29*18)/118 -> 0 | G29: =PRODUCT(B29*D29) -> 0 | H29: =SUM(F29:G29) -> 0
A30: OTHER | E30: =PRODUCT(B30*C30) -> 0 | F30: =PRODUCT(E30*18)/118 -> 0 | G30: =PRODUCT(B30*D30) -> 0 | H30: =SUM(F30:G30) -> 0
A31: OTHER | E31: =PRODUCT(B31*C31) -> 0 | F31: =PRODUCT(E31*18)/118 -> 0 | G31: =PRODUCT(B31*D31) -> 0 | H31: =SUM(F31:G31) -> 0
... A36: OTHER | E36: =PRODUCT(B36*C36) -> 0 | F36: =PRODUCT(E36*18)/118 -> 0 | G36: =PRODUCT(B36*D36) -> 0 | H36: =SUM(F36:G36) -> 0
A37: TOTALY | E37: =SUM(E5:E36) -> 105460814 | F37: =SUM(F5:F36) -> 16087243 | G37: =SUM(G5:G36) -> 1381030 | H37: =SUM(H5:H36) -> 17468273
A38: SUMMARY | C38: RWF | E38: NAME | G38: Phone | H38: RWF
A39: TOTAL RWF PAID ON MOMO PAY
A40: TOTAL RWF PAID ON CASH
A41: AMOUNT NOT INVOICED
A42: TOTAL RWF DEPPOSITED ON BANK
A43: MEMBERSHIP FEES REGISTRETION
A44: MEMBERSHIP FEES CONTRIBUTION
A45: TOTAL INCOME | C45: =SUM(C39+C40+C41+C42+C43+C44) -> 0
A46: TIMBER SUMMARY
...

Sheet HUYE
A1: QUANTITY REPORT
A3: MONTHLY REPORT OF MAY 2026
A5: NAME OF TIMBER | B5: No OF TIMBER | C5: PRICE OF TIMBER | E5: TOTAL COST | F5: TVA | G5: MSF | H5: TVA+MSF
A6: PINUS NINI | B6: 232 | C6: 8260 | E6: =PRODUCT(B6*C6) -> 1916320 | F6: =PRODUCT(E6*18)/118 -> 292320 | G6: =PRODUCT(B6*50) -> 11600 | H6: =SUM(F6:G6) -> 303920
A7: Pinus | B7: 572 | C7: 9440 | E7: =PRODUCT(B7*C7) -> 5399680 | F7: =PRODUCT(E7*18)/118 -> 823680 | G7: =PRODUCT(B7*50) -> 28600 | H7: =SUM(F7:G7) -> 852280
A8: PINUS | B8: 175 | C8: 7000 | E8: =PRODUCT(B8*C8) -> 1225000 | F8: =PRODUCT(E8*18)/118 -> 186864.41 | G8: =PRODUCT(B8*50) -> 8750 | H8: =SUM(F8:G8) -> 195614.41
A9: MADIRIYE NINI | B9: 53 | C9: 3540 | E9: =PRODUCT(B9*C9) -> 187620 | F9: =PRODUCT(E9*18)/118 -> 28620 | G9: =PRODUCT(B9*30) -> 1590 | H9: =SUM(F9:G9) -> 30210
A10: MADIRIYE NTOYA | B10: 22285 | C10: 2360 | E10: =PRODUCT(B10*C10) -> 52592600 | F10: =PRODUCT(E10*18)/118 -> 8022600 | G10: =PRODUCT(B10*30) -> 668550 | H10: =SUM(F10:G10) -> 8691150
A11: GEREVERIYA | C11: 1180 | E11: =PRODUCT(B11*C11) -> 0 | F11: =PRODUCT(E11*18)/118 -> 0 | G11: =PRODUCT(B11*30) -> 0 | H11: =SUM(F11:G11) -> 0
A12: MADRIEN | B12: 2782 | C12: 4130 | E12: =PRODUCT(B12*C12) -> 11489660 | F12: =PRODUCT(E12*18)/118 -> 1752660 | G12: =PRODUCT(B12*30) -> 83460 | H12: =SUM(F12:G12) -> 1836120
A13: PLANCHE | B13: 3381 | C13: 1180 | E13: =PRODUCT(B13*C13) -> 3989580 | F13: =PRODUCT(E13*18)/118 -> 608580 | G13: =PRODUCT(B13*20) -> 67620 | H13: =SUM(F13:G13) -> 676200
A14: GEREVERIYA | C14: 1180 | E14: =PRODUCT(B14*C14) -> 0 | F14: =PRODUCT(E14*18)/118 -> 0 | G14: =PRODUCT(B14*20) -> 0 | H14: =SUM(F14:G14) -> 0
A15: Other Timber for Difference Price
A16: NAME OF TIMBER | B16: No OF TIMBER | C16: P/U | D16: MSF | E16: TOTAL COST | F16: VAT | G16: MSF | H16: VTA+MST
A17: IBIPANDE | B17: 1681 | C17: 2950 | D17: 50 | E17: =PRODUCT(B17*C17) -> 4958950 | F17: =PRODUCT(E17*18)/118 -> 756450 | G17: =PRODUCT(B17*D17) -> 84050 | H17: =SUM(F17:G17) -> 840500
A18: IBIPANDE BYA PINUS | B18: 2536 | C18: 2360 | D18: 50 | E18: =PRODUCT(B18*C18) -> 5984960 | F18: =PRODUCT(E18*18)/118 -> 912960 | G18: =PRODUCT(B18*D18) -> 126800 | H18: =SUM(F18:G18) -> 1039760
A19: SIPURE | B19: 2000 | C19: 1180 | D19: 20 | E19: =PRODUCT(B19*C19) -> 2360000 | F19: =PRODUCT(E19*18)/118 -> 360000 | G19: =PRODUCT(B19*D19) -> 40000 | H19: =SUM(F19:G19) -> 400000
A20: SEDERERA | B20: 130 | C20: 1180 | D20: 20 | E20: =PRODUCT(B20*C20) -> 153400 | F20: =PRODUCT(E20*18)/118 -> 23400 | G20: =PRODUCT(B20*D20) -> 2600 | H20: =SUM(F20:G20) -> 26000
A21: DECHETS | B21: 220 | C21: 10000 | D21: 1500 | E21: =PRODUCT(B21*C21) -> 2200000 | F21: =PRODUCT(E21*18)/118 -> 335593.22 | G21: =PRODUCT(B21*D21) -> 330000 | H21: =SUM(F21:G21) -> 665593.22
A22: DECHETS | E22: =PRODUCT(B22*C22) -> 0 | F22: =PRODUCT(E22*18)/118 -> 0 | G22: =PRODUCT(B22*D22) -> 0 | H22: =SUM(F22:G22) -> 0
A23: OTHER | E23: =PRODUCT(B23*C23) -> 0 | F23: =PRODUCT(E23*18)/118 -> 0 | G23: =PRODUCT(B23*D23) -> 0 | H23: =SUM(F23:G23) -> 0
A24: OTHER | E24: =PRODUCT(B24*C24) -> 0 | F24: =PRODUCT(E24*18)/118 -> 0 | G24: =PRODUCT(B24*D24) -> 0 | H24: =SUM(F24:G24) -> 0
A25: OTHER | E25: =PRODUCT(B25*C25) -> 0 | F25: =PRODUCT(E25*18)/118 -> 0 | G25: =PRODUCT(B25*D25) -> 0 | H25: =SUM(F25:G25) -> 0
A26: OTHER | E26: =PRODUCT(B26*C26) -> 0 | F26: =PRODUCT(E26*18)/118 -> 0 | G26: =PRODUCT(B26*D26) -> 0 | H26: =SUM(F26:G26) -> 0
A27: OTHER | E27: =PRODUCT(B27*C27) -> 0 | F27: =PRODUCT(E27*18)/118 -> 0 | G27: =PRODUCT(B27*D27) -> 0 | H27: =SUM(F27:G27) -> 0
A28: OTHER | E28: =PRODUCT(B28*C28) -> 0 | F28: =PRODUCT(E28*18)/118 -> 0 | G28: =PRODUCT(B28*D28) -> 0 | H28: =SUM(F28:G28) -> 0
A29: OTHER | E29: =PRODUCT(B29*C29) -> 0 | F29: =PRODUCT(E29*18)/118 -> 0 | G29: =PRODUCT(B29*D29) -> 0 | H29: =SUM(F29:G29) -> 0
A30: OTHER | E30: =PRODUCT(B30*C30) -> 0 | F30: =PRODUCT(E30*18)/118 -> 0 | G30: =PRODUCT(B30*D30) -> 0 | H30: =SUM(F30:G30) -> 0
A31: OTHER | E31: =PRODUCT(B31*C31) -> 0 | F31: =PRODUCT(E31*18)/118 -> 0 | G31: =PRODUCT(B31*D31) -> 0 | H31: =SUM(F31:G31) -> 0
A32: OTHER | E32: =PRODUCT(B32*C32) -> 0 | F32: =PRODUCT(E32*18)/118 -> 0 | G32: =PRODUCT(B32*D32) -> 0 | H32: =SUM(F32:G32) -> 0
A33: OTHER | E33: =PRODUCT(B33*C33) -> 0 | F33: =PRODUCT(E33*18)/118 -> 0 | G33: =PRODUCT(B33*D33) -> 0 | H33: =SUM(F33:G33) -> 0
... A36: OTHER | E36: =PRODUCT(B36*C36) -> 0 | F36: =PRODUCT(E36*18)/118 -> 0 | G36: =PRODUCT(B36*D36) -> 0 | H36: =SUM(F36:G36) -> 0
A37: TOTALY | E37: =SUM(E5:E36) -> 92457770 | F37: =SUM(F5:F36) -> 14103728 | G37: =SUM(G5:G36) -> 1453620 | H37: =SUM(H5:H36) -> 15557348
A38: SUMMARY | C38: RWF | E38: NAME | G38: Phone | H38: RWF
A39: TOTAL RWF PAID ON MOMO PAY
A40: TOTAL RWF PAID ON CASH
A41: AMOUNT NOT INVOICED
A42: TOTAL RWF DEPPOSITED ON BANK
A43: MEMBERSHIP FEES REGISTRETION
A44: MEMBERSHIP FEES CONTRIBUTION
...

Sheet NYAMAGABE
A1: QUANTITY REPORT
A3: MONTHLY REPORT OF MAY 2026
A5: NAME OF TIMBER | B5: No OF TIMBER | C5: PRICE OF TIMBER | E5: TOTAL COST | F5: TVA | G5: MSF | H5: TVA+MSF
A6: PINUS NINI | E6: =PRODUCT(B6*C6) -> 0 | F6: =PRODUCT(E6*18)/118 -> 0 | G6: =PRODUCT(B6*50) -> 0 | H6: =SUM(F6:G6) -> 0
A7: PINUS NTOYA | C7: 7000 | E7: =PRODUCT(B7*C7) -> 0 | F7: =PRODUCT(E7*18)/118 -> 0 | G7: =PRODUCT(B7*50) -> 0 | H7: =SUM(F7:G7) -> 0
A8: PINUS | C8: 8260 | E8: =PRODUCT(B8*C8) -> 0 | F8: =PRODUCT(E8*18)/118 -> 0 | G8: =PRODUCT(B8*50) -> 0 | H8: =SUM(F8:G8) -> 0
A9: MADIRIYE NINI | E9: =PRODUCT(B9*C9) -> 0 | F9: =PRODUCT(E9*18)/118 -> 0 | G9: =PRODUCT(B9*30) -> 0 | H9: =SUM(F9:G9) -> 0
A10: MADIRIYE NTOYA | C10: 2360 | E10: =PRODUCT(B10*C10) -> 0 | F10: =PRODUCT(E10*18)/118 -> 0 | G10: =PRODUCT(B10*30) -> 0 | H10: =SUM(F10:G10) -> 0
A11: MADRIEN | E11: =PRODUCT(B11*C11) -> 0 | F11: =PRODUCT(E11*18)/118 -> 0 | G11: =PRODUCT(B11*30) -> 0 | H11: =SUM(F11:G11) -> 0
A12: MADRIEN | E12: =PRODUCT(B12*C12) -> 0 | F12: =PRODUCT(E12*18)/118 -> 0 | G12: =PRODUCT(B12*30) -> 0 | H12: =SUM(F12:G12) -> 0
A13: PLANCHE | C13: 1180 | E13: =PRODUCT(B13*C13) -> 0 | F13: =PRODUCT(E13*18)/118 -> 0 | G13: =PRODUCT(B13*20) -> 0 | H13: =SUM(F13:G13) -> 0
A14: PLANCHE | E14: =PRODUCT(B14*C14) -> 0 | F14: =PRODUCT(E14*18)/118 -> 0 | G14: =PRODUCT(B14*20) -> 0 | H14: =SUM(F14:G14) -> 0
A15: Other Timber for Difference Price
A16: NAME OF TIMBER | B16: No OF TIMBER | C16: P/U | D16: MSF | E16: TOTAL COST | F16: VAT | G16: MSF | H16: VTA+MST
A17: IBIPANDE BYA PINUS | D17: 50 | E17: =PRODUCT(B17*C17) -> 0 | F17: =PRODUCT(E17*18)/118 -> 0 | G17: =PRODUCT(B17*D17) -> 0 | H17: =SUM(F17:G17) -> 0
A18: IBIPANDE BYA PINUS | D18: 50 | E18: =PRODUCT(B18*C18) -> 0 | F18: =PRODUCT(E18*18)/118 -> 0 | G18: =PRODUCT(B18*D18) -> 0 | H18: =SUM(F18:G18) -> 0
A19: UMUSAVE | E19: =PRODUCT(B19*C19) -> 0 | F19: =PRODUCT(E19*18)/118 -> 0 | G19: =PRODUCT(B19*D19) -> 0 | H19: =SUM(F19:G19) -> 0
A20: UMUSAVE | E20: =PRODUCT(B20*C20) -> 0 | F20: =PRODUCT(E20*18)/118 -> 0 | G20: =PRODUCT(B20*D20) -> 0 | H20: =SUM(F20:G20) -> 0
A21: OTHER | E21: =PRODUCT(B21*C21) -> 0 | F21: =PRODUCT(E21*18)/118 -> 0 | G21: =PRODUCT(B21*D21) -> 0 | H21: =SUM(F21:G21) -> 0
A22: OTHER | E22: =PRODUCT(B22*C22) -> 0 | F22: =PRODUCT(E22*18)/118 -> 0 | G22: =PRODUCT(B22*D22) -> 0 | H22: =SUM(F22:G22) -> 0
A23: OTHER | E23: =PRODUCT(B23*C23) -> 0 | F23: =PRODUCT(E23*18)/118 -> 0 | G23: =PRODUCT(B23*D23) -> 0 | H23: =SUM(F23:G23) -> 0
A24: OTHER | E24: =PRODUCT(B24*C24) -> 0 | F24: =PRODUCT(E24*18)/118 -> 0 | G24: =PRODUCT(B24*D24) -> 0 | H24: =SUM(F24:G24) -> 0
A25: OTHER | E25: =PRODUCT(B25*C25) -> 0 | F25: =PRODUCT(E25*18)/118 -> 0 | G25: =PRODUCT(B25*D25) -> 0 | H25: =SUM(F25:G25) -> 0
A26: OTHER | E26: =PRODUCT(B26*C26) -> 0 | F26: =PRODUCT(E26*18)/118 -> 0 | G26: =PRODUCT(B26*D26) -> 0 | H26: =SUM(F26:G26) -> 0
A27: OTHER | E27: =PRODUCT(B27*C27) -> 0 | F27: =PRODUCT(E27*18)/118 -> 0 | G27: =PRODUCT(B27*D27) -> 0 | H27: =SUM(F27:G27) -> 0
A28: OTHER | E28: =PRODUCT(B28*C28) -> 0 | F28: =PRODUCT(E28*18)/118 -> 0 | G28: =PRODUCT(B28*D28) -> 0 | H28: =SUM(F28:G28) -> 0
A29: OTHER | E29: =PRODUCT(B29*C29) -> 0 | F29: =PRODUCT(E29*18)/118 -> 0 | G29: =PRODUCT(B29*D29) -> 0 | H29: =SUM(F29:G29) -> 0
A30: OTHER | E30: =PRODUCT(B30*C30) -> 0 | F30: =PRODUCT(E30*18)/118 -> 0 | G30: =PRODUCT(B30*D30) -> 0 | H30: =SUM(F30:G30) -> 0
... A36: OTHER | E36: =PRODUCT(B36*C36) -> 0 | F36: =PRODUCT(E36*18)/118 -> 0 | G36: =PRODUCT(B36*D36) -> 0 | H36: =SUM(F36:G36) -> 0
A37: TOTALY | E37: =SUM(E5:E36) -> 0 | F37: =SUM(F5:F36) -> 0 | G37: =SUM(G5:G36) -> 0 | H37: =SUM(H5:H36) -> 0
A38: SUMMARY | C38: RWF | E38: NAME | G38: Phone | H38: RWF
A39: TOTAL RWF PAID ON MOMO PAY | C39: 316500
A40: TOTAL RWF PAID ON CASH
A41: AMOUNT NOT INVOICED
A42: TOTAL RWF DEPPOSITED ON BANK
A43: MEMBERSHIP FEES REGISTRETION
A44: MEMBERSHIP FEES CONTRIBUTION
A45: TOTAL INCOME | C45: =SUM(C39+C40+C41+C42+C43+C44) -> 316500
A46: TIMBER SUMMARY
A48: REPORT SUMMARY | C48: TIMBER TYPE | E48: NUMBER OF QUANTITY
...

Sheet KAYONZA
A1: QUANTITY REPORT
A3: MONTHLY REPORT OF MAY 2026
A5: NAME OF TIMBER | B5: No OF TIMBER | C5: PRICE OF TIMBER | E5: TOTAL COST | F5: TVA | G5: MSF | H5: TVA+MSF
A6: PINUS NINI | E6: =PRODUCT(B6*C6) -> 0 | F6: =PRODUCT(E6*18)/118 -> 0 | G6: =PRODUCT(B6*50) -> 0 | H6: =SUM(F6:G6) -> 0
A7: PINUS NTOYA | B7: 580 | C7: 5900 | E7: =PRODUCT(B7*C7) -> 3422000 | F7: =PRODUCT(E7*18)/118 -> 522000 | G7: =PRODUCT(B7*50) -> 29000 | H7: =SUM(F7:G7) -> 551000
A8: PINUS | E8: =PRODUCT(B8*C8) -> 0 | F8: =PRODUCT(E8*18)/118 -> 0 | G8: =PRODUCT(B8*50) -> 0 | H8: =SUM(F8:G8) -> 0
A9: MADIRIYE NINI | E9: =PRODUCT(B9*C9) -> 0 | F9: =PRODUCT(E9*18)/118 -> 0 | G9: =PRODUCT(B9*30) -> 0 | H9: =SUM(F9:G9) -> 0
A10: MADIRIYE NTOYA | E10: =PRODUCT(B10*C10) -> 0 | F10: =PRODUCT(E10*18)/118 -> 0 | G10: =PRODUCT(B10*30) -> 0 | H10: =SUM(F10:G10) -> 0
A11: MADRIEN | B11: 19315 | C11: 2124 | E11: =PRODUCT(B11*C11) -> 41025060 | F11: =PRODUCT(E11*18)/118 -> 6258060 | G11: =PRODUCT(B11*30) -> 579450 | H11: =SUM(F11:G11) -> 6837510
A12: MADRIEN | E12: =PRODUCT(B12*C12) -> 0 | F12: =PRODUCT(E12*18)/118 -> 0 | G12: =PRODUCT(B12*30) -> 0 | H12: =SUM(F12:G12) -> 0
A13: PLANCHE | B13: 3310 | C13: 1357 | E13: =PRODUCT(B13*C13) -> 4491670 | F13: =PRODUCT(E13*18)/118 -> 685170 | G13: =PRODUCT(B13*20) -> 66200 | H13: =SUM(F13:G13) -> 751370
A14: PLANCHE | E14: =PRODUCT(B14*C14) -> 0 | F14: =PRODUCT(E14*18)/118 -> 0 | G14: =PRODUCT(B14*20) -> 0 | H14: =SUM(F14:G14) -> 0
A15: Other Timber for Difference Price
A16: NAME OF TIMBER | B16: No OF TIMBER | C16: P/U | D16: MSF | E16: TOTAL COST | F16: VAT | G16: MSF | H16: VTA+MST
A17: IBIPANDE | B17: 2366 | C17: 1180 | D17: 20 | E17: =PRODUCT(B17*C17) -> 2791880 | F17: =PRODUCT(E17*18)/118 -> 425880 | G17: =PRODUCT(B17*D17) -> 47320 | H17: =SUM(F17:G17) -> 473200
A18: GEREVERIYA | D18: 20 | E18: =PRODUCT(B18*C18) -> 0 | F18: =PRODUCT(E18*18)/118 -> 0 | G18: =PRODUCT(B18*D18) -> 0 | H18: =SUM(F18:G18) -> 0
A19: UMUSAVE | D19: 200 | E19: =PRODUCT(B19*C19) -> 0 | F19: =PRODUCT(E19*18)/118 -> 0 | G19: =PRODUCT(B19*D19) -> 0 | H19: =SUM(F19:G19) -> 0
A20: IBIPANDE BYA SIPURE | D20: 354 | E20: =PRODUCT(B20*C20) -> 0 | F20: =PRODUCT(E20*18)/118 -> 0 | G20: =PRODUCT(B20*D20) -> 0 | H20: =SUM(F20:G20) -> 0
A21: OTHER | D21: 354 | E21: =PRODUCT(B21*C21) -> 0 | F21: =PRODUCT(E21*18)/118 -> 0 | G21: =PRODUCT(B21*D21) -> 0 | H21: =SUM(F21:G21) -> 0
A22: OTHER | D22: 30 | E22: =PRODUCT(B22*C22) -> 0 | F22: =PRODUCT(E22*18)/118 -> 0 | G22: =PRODUCT(B22*D22) -> 0 | H22: =SUM(F22:G22) -> 0
A23: OTHER | E23: =PRODUCT(B23*C23) -> 0 | F23: =PRODUCT(E23*18)/118 -> 0 | G23: =PRODUCT(B23*D23) -> 0 | H23: =SUM(F23:G23) -> 0
A24: OTHER | E24: =PRODUCT(B24*C24) -> 0 | F24: =PRODUCT(E24*18)/118 -> 0 | G24: =PRODUCT(B24*D24) -> 0 | H24: =SUM(F24:G24) -> 0
A25: OTHER | E25: =PRODUCT(B25*C25) -> 0 | F25: =PRODUCT(E25*18)/118 -> 0 | G25: =PRODUCT(B25*D25) -> 0 | H25: =SUM(F25:G25) -> 0
A26: OTHER | E26: =PRODUCT(B26*C26) -> 0 | F26: =PRODUCT(E26*18)/118 -> 0 | G26: =PRODUCT(B26*D26) -> 0 | H26: =SUM(F26:G26) -> 0
A27: OTHER | E27: =PRODUCT(B27*C27) -> 0 | F27: =PRODUCT(E27*18)/118 -> 0 | G27: =PRODUCT(B27*D27) -> 0 | H27: =SUM(F27:G27) -> 0
A28: OTHER | E28: =PRODUCT(B28*C28) -> 0 | F28: =PRODUCT(E28*18)/118 -> 0 | G28: =PRODUCT(B28*D28) -> 0 | H28: =SUM(F28:G28) -> 0
A29: OTHER | E29: =PRODUCT(B29*C29) -> 0 | F29: =PRODUCT(E29*18)/118 -> 0 | G29: =PRODUCT(B29*D29) -> 0 | H29: =SUM(F29:G29) -> 0
A30: OTHER | E30: =PRODUCT(B30*C30) -> 0 | F30: =PRODUCT(E30*18)/118 -> 0 | G30: =PRODUCT(B30*D30) -> 0 | H30: =SUM(F30:G30) -> 0
A31: OTHER | E31: =PRODUCT(B31*C31) -> 0 | F31: =PRODUCT(E31*18)/118 -> 0 | G31: =PRODUCT(B31*D31) -> 0 | H31: =SUM(F31:G31) -> 0
A32: OTHER | E32: =PRODUCT(B32*C32) -> 0 | F32: =PRODUCT(E32*18)/118 -> 0 | G32: =PRODUCT(B32*D32) -> 0 | H32: =SUM(F32:G32) -> 0
A33: OTHER | E33: =PRODUCT(B33*C33) -> 0 | F33: =PRODUCT(E33*18)/118 -> 0 | G33: =PRODUCT(B33*D33) -> 0 | H33: =SUM(F33:G33) -> 0
A34: OTHER | E34: =PRODUCT(B34*C34) -> 0 | F34: =PRODUCT(E34*18)/118 -> 0 | G34: =PRODUCT(B34*D34) -> 0 | H34: =SUM(F34:G34) -> 0
... A36: OTHER | E36: =PRODUCT(B36*C36) -> 0 | F36: =PRODUCT(E36*18)/118 -> 0 | G36: =PRODUCT(B36*D36) -> 0 | H36: =SUM(F36:G36) -> 0
A37: TOTALY | E37: =SUM(E5:E36) -> 51730610 | F37: =SUM(F5:F36) -> 7891110 | G37: =SUM(G5:G36) -> 721970 | H37: =SUM(H5:H36) -> 8613080
A38: SUMMARY | C38: RWF | E38: NAME | G38: Phone | H38: RWF
A39: TOTAL RWF PAID ON MOMO PAY | C39: 8926280
A40: TOTAL RWF PAID ON CASH
A41: AMOUNT NOT INVOICED
A42: TOTAL RWF DEPPOSITED ON BANK
A43: MEMBERSHIP FEES REGISTRETION
...

Sheet RUHANGO
A1: QUANTITY REPORT
A3: MONTHLY REPORT OF MAY 2026
A5: NAME OF TIMBER | B5: No OF TIMBER | C5: PRICE OF TIMBER | E5: TOTAL COST | F5: TVA | G5: MSF | H5: TVA+MSF
A6: PINUS NINI | E6: =PRODUCT(B6*C6) -> 0 | F6: =PRODUCT(E6*18)/118 -> 0 | G6: =PRODUCT(B6*50) -> 0 | H6: =SUM(F6:G6) -> 0
A7: PINUS NTOYA | E7: =PRODUCT(B7*C7) -> 0 | F7: =PRODUCT(E7*18)/118 -> 0 | G7: =PRODUCT(B7*50) -> 0 | H7: =SUM(F7:G7) -> 0
A8: PINUS | E8: =PRODUCT(B8*C8) -> 0 | F8: =PRODUCT(E8*18)/118 -> 0 | G8: =PRODUCT(B8*50) -> 0 | H8: =SUM(F8:G8) -> 0
A9: MADIRIYE NINI | B9: 700 | C9: 2300 | E9: =PRODUCT(B9*C9) -> 1610000 | F9: =PRODUCT(E9*18)/118 -> 245593.22 | G9: =PRODUCT(B9*30) -> 21000 | H9: =SUM(F9:G9) -> 266593.22
A10: MADIRIYE NTOYA | B10: 5320 | C10: 1800 | E10: =PRODUCT(B10*C10) -> 9576000 | F10: =PRODUCT(E10*18)/118 -> 1460745.8 | G10: =PRODUCT(B10*30) -> 159600 | H10: =SUM(F10:G10) -> 1620345.8
A11: MADRIEN | B11: 200 | C11: 2500 | E11: =PRODUCT(B11*C11) -> 500000 | F11: =PRODUCT(E11*18)/118 -> 76271.186 | G11: =PRODUCT(B11*30) -> 6000 | H11: =SUM(F11:G11) -> 82271.186
A12: MADRIEN | E12: =PRODUCT(B12*C12) -> 0 | F12: =PRODUCT(E12*18)/118 -> 0 | G12: =PRODUCT(B12*30) -> 0 | H12: =SUM(F12:G12) -> 0
A13: PLANCHE | B13: 100 | C13: 1200 | E13: =PRODUCT(B13*C13) -> 120000 | F13: =PRODUCT(E13*18)/118 -> 18305.085 | G13: =PRODUCT(B13*20) -> 2000 | H13: =SUM(F13:G13) -> 20305.085
A14: PLANCHE | E14: =PRODUCT(B14*C14) -> 0 | F14: =PRODUCT(E14*18)/118 -> 0 | G14: =PRODUCT(B14*20) -> 0 | H14: =SUM(F14:G14) -> 0
A15: Other Timber for Difference Price
